Workbook

Sheet ST.SALES
B2: S.NO | C2: NAME OF STOCKIST | D2: HQ | E2: CONTACT NUMBER | F2: NAME OF PROPRIETOR | G2: APR | I2: MAY | K2: JUN | M2: JUL | O2: AUG | Q2: SEP | S2: OCT | U2: NOV | W2: DEC | Y2: JAN | AA2: FEB | AC2: MAR | AE2: LAST YEAR TOTAL SALES APRIL'21-MARCH'22 | AF2: AVERAGE SALES LAST YEAR 2022-2023
C4: AHMEDABAD
B5: 1 | C5: 1006809:DHRUVI PHARMA PVT. LTD.--GOTA, AHMEDABAD | D5: AHMEDABAD | AE5: 9.13722
B6: 2 | C6: 1001556:ANKUR DISTRIBUTORS--AHMEDABAD | D6: AHMEDABAD | AE6: 4.49569
B7: 3 | C7: 1001584:K.S.PHARMA--AHMEDABAD | D7: AHMEDABAD | AE7: 4.32667
B8: 4 | C8: 1001585:K.B.SHAH & CO.--AHMEDABAD | D8: AHMEDABAD | AE8: 3.69266
B9: 5 | C9: 1001611:R.AMRATLAL & COMPANY--AHMEDABAD | D9: AHMEDABAD | AE9: 3.667
B10: 6 | C10: 1002005:D.K.PHARMA--AHMEDABAD | D10: AHMEDABAD | AE10: 3.1623
B11: 7 | C11: 1001562:BELA DRUG CENTRE--AHMEDABAD | D11: AHMEDABAD | AE11: 3.00415
B12: 8 | C12: 1001984:SHRIJI DISTRIBUTORS--AHMEDABAD | D12: AHMEDABAD | AE12: 2.52698
B13: 9 | C13: 1001582:JOSHI BROTHERS--HIMATNAGAR | D13: AHMEDABAD | AE13: 1.99783
B14: 10 | C14: 1001587:MONO CHEMIST--AHMEDABAD | D14: AHMEDABAD | AE14: 1.8647
B15: 11 | C15: 1001618:SAHYOG AGENCIES (AHMEDABAD)--AHMEDABAD | D15: AHMEDABAD | AE15: 1.79198
B16: 12 | C16: 1001629:SHREEJI PHARMADEAL PVT LTD--GANDHINAGAR | D16: AHMEDABAD | AE16: 1.63734
... B29: 25 | C29: 1001570:DHRUVIL MEDICINES--MODASA | D29: AHMEDABAD | AE29: 0.11912
C34: TOTAL
C35: MEHSANA
B36: 1 | C36: 1001606:RAMESH PHARMA DISTRIBUTORS--KALOL | D36: MEHSANA | AE36: 2.41077
B37: 2 | C37: 1001635:V.V. PHARMA--UNJHA | D37: MEHSANA | AE37: 2.06653
B38: 3 | C38: 1001597:PATEL MEDICAL STORES--DEESA | D38: MEHSANA | AE38: 1.68514
B39: 4 | C39: 1001557:ATUL MEDICAL AGENCY--SIDDHPUR | D39: MEHSANA | AE39: 1.55412
B40: 5 | C40: 1001614:SHARDA MEDICAL AGENCIES--PALANPUR | D40: MEHSANA | AE40: 1.06762
B41: 6 | C41: 1001554:ARAVALLI MARKETING--MEHSANA | D41: MEHSANA | AE41: 0.77165
B42: 7 | C42: 1001571:GANDHI MEDICAL AGENCY--PATAN | D42: MEHSANA | AE42: 0.70692
B43: 8 | C43: 1003119:SHREEJI PHARMA DISTRIBUTORS--DHANERA | D43: MEHSANA | AE43: 0.3865
B44: 9 | C44: 1001563:B.M.K.DISTRIBUTORS--VISNAGAR | D44: MEHSANA | AE44: 0.31315
B45: 10 | C45: 1023988:JIGAR MEDICAL AGENCY--RADHANPUR | D45: MEHSANA | AE45: 0.2089
B46: 11 | C46: 1001615:SEVENTILAL POPATLAL & COM--MEHSANA | D46: MEHSANA | AE46: 0.0268
C51: TOTAL
C52: BHAVNAGAAR
B53: 1 | C53: 1001569:DHAVAL MARKETING CORPORATION--BHAVNAGAR | D53: BHAVNAGAR | AE53: 3.33643
B54: 2 | C54: 1001572:GENERAL MEDICAL STORES--BHAVNAGAR | D54: BHAVNAGAR | AE54: 2.88518
B55: 3 | C55: 1001578:HARIKRISHNA MEDICAL AGENCY--AMRELI | D55: BHAVNAGAR | AE55: 2.25261
B56: 4 | C56: 1001595:PARIKH MEDICAL STORES--AMRELI | D56: BHAVNAGAR | AE56: 2.07329
B57: 5 | C57: 1001621:SUN PHARMA DISTRIBUTORS--BHAVNAGAR | D57: BHAVNAGAR | AE57: 1.98376
B58: 6 | C58: 1001623:SHANTI MEDICAL AGENCY--MAHUVA | D58: BHAVNAGAR | AE58: 1.91523
B59: 7 | C59: 1001632:UMA AGENCIES--BHAVNAGAR | D59: BHAVNAGAR | AE59: 1.88626
C62: TOTAL
C63: BHUJ
B64: 1 | C64: 1001575:H. SHANTILAL AGENCIES--BHUJ | D64: BHUJ | AE64: 1.80696
...

Sheet SUMMATY
B3: 2023-2024 | C3: April'2023 | E3: May'2023 | G3: June'2023 | I3: July'2023 | K3: August'2023 | M3: Sept'2023 | O3: Oct'2023 | Q3: Nov'2023 | S3: Dec'2023 | U3: Jan'2024 | W3: Feb'2024 | Y3: March'2024 | AA3: TOTAL
B4: HQ | C4: Sec Sales | D4: Closing stock | E4: Sec Sales | F4: Closing stock | G4: Sec Sales | H4: Closing stock | I4: Sec Sales | J4: Closing stock | K4: Sec Sales | L4: Closing stock | M4: Sec Sales | N4: Closing stock | O4: Sec Sales | P4: Closing stock | Q4: Sec Sales | R4: Closing stock | S4: Sec Sales | T4: Closing stock | U4: Sec Sales | V4: Closing stock | W4: Sec Sales | X4: Closing stock | Y4: Sec Sales | Z4: Closing stock | AA4: SEC CUM | AB4: STOCK CUM
B6: AHMEDABAD POOL | C6: =AHMEDABAD!E24 -> 5.3340786 | D6: =AHMEDABAD!F24 -> 7.9204852 | E6: =AHMEDABAD!G24 -> 0 | F6: =AHMEDABAD!H24 -> 0 | G6: =AHMEDABAD!I24 -> 4.8221078 | H6: =AHMEDABAD!J24 -> 8.9534293 | I6: =AHMEDABAD!K24 -> 0.4989278 | J6: =AHMEDABAD!L24 -> 1.7515441
B7: MEHSANA | C7: =MEHSANA!E24 -> 2.089979 | D7: =MEHSANA!F24 -> 2.2861055 | E7: =MEHSANA!G24 -> 0 | F7: =MEHSANA!H24 -> 0 | G7: =AHMEDABAD!I25 -> 0 | H7: =AHMEDABAD!J25 -> 0 | I7: =AHMEDABAD!K25 -> 0 | J7: =AHMEDABAD!L25 -> 0
B8: DM AHMEDABAD | C8: ='DM ABAD'!E17 -> 8.2608552 | D8: ='DM ABAD'!F17 -> 11.201961 | E8: ='DM ABAD'!G17 -> 0 | F8: ='DM ABAD'!H17 -> 0 | G8: ='DM ABAD'!I17 -> 6.9846222 | H8: ='DM ABAD'!J17 -> 12.662306 | I8: ='DM ABAD'!K17 -> 0.6481008 | J8: ='DM ABAD'!L17 -> 1.7580471
B10: RAJKOT | C10: =RAJKOT!E23 -> 0.120244 | D10: =RAJKOT!F23 -> 0.2698128 | E10: =RAJKOT!G23 -> 0 | F10: =RAJKOT!H23 -> 0 | G10: =RAJKOT!I23 -> 0 | H10: =RAJKOT!J23 -> 0 | I10: =RAJKOT!K23 -> 0 | J10: =RAJKOT!L23 -> 0
B11: JUNAGADH | C11: =JUNAGADH!E24 -> 3.1691421 | D11: =JUNAGADH!F24 -> 3.6640293 | E11: =JUNAGADH!G24 -> 0 | F11: =JUNAGADH!H24 -> 0 | G11: =JUNAGADH!I24 -> 0 | H11: =JUNAGADH!J24 -> 0 | I11: =JUNAGADH!K24 -> 0 | J11: =JUNAGADH!L24 -> 0
B12: BHAVNAGAR | C12: =BHAVNAGAR!E24 -> 0.4463557 | D12: =BHAVNAGAR!F24 -> 1.1711222 | E12: =BHAVNAGAR!G24 -> 0 | F12: =BHAVNAGAR!H24 -> 0 | G12: =BHAVNAGAR!I24 -> 0 | H12: =BHAVNAGAR!J24 -> 0 | I12: =BHAVNAGAR!K24 -> 0 | J12: =BHAVNAGAR!L24 -> 0
B13: BAHUJ | C13: =BHUJ!E24 -> 0.6264603 | D13: =BHUJ!F24 -> 1.1933022 | E13: =BHUJ!G24 -> 0 | F13: =BHUJ!H24 -> 0 | G13: =BHUJ!I24 -> 0 | H13: =BHUJ!J24 -> 0 | I13: =BHUJ!K24 -> 0 | J13: =BHUJ!L24 -> 0
B14: DM RAJKOT | C14: ='DM RAJKOT'!E17 -> 7.0332389 | D14: ='DM RAJKOT'!F17 -> 8.6761401 | E14: ='DM RAJKOT'!G17 -> 0 | F14: ='DM RAJKOT'!H17 -> 0 | G14: ='DM RAJKOT'!I17 -> 0 | H14: ='DM RAJKOT'!J17 -> 0 | I14: ='DM RAJKOT'!K17 -> 0 | J14: ='DM RAJKOT'!L17 -> 0
B16: SURAT POOL | C16: =SURAT!E19 -> S.S. | D16: =SURAT!F19 -> C.S. | E16: =SURAT!G19 -> S.S. | F16: =SURAT!H19 -> C.S. | G16: =SURAT!I19 -> S.S. | H16: =SURAT!J19 -> C.S. | I16: =SURAT!K19 -> S.S. | J16: =SURAT!L19 -> C.S.
B17: BARODA POOL | C17: =BARODA!E19 -> S.S. | D17: =BARODA!F19 -> C.S. | E17: =BARODA!G19 -> S.S. | F17: =BARODA!H19 -> C.S. | G17: =BARODA!I19 -> S.S. | H17: =BARODA!J19 -> C.S. | I17: =BARODA!K19 -> S.S. | J17: =BARODA!L19 -> C.S.
B18: DM SURAT | C18: ='DM SURAT'!E17 -> 11.099668 | D18: ='DM SURAT'!F17 -> 15.723923 | E18: ='DM SURAT'!G17 -> 5.8869149 | F18: ='DM SURAT'!H17 -> 7.6019522 | G18: ='DM SURAT'!I17 -> 5.5947475 | H18: ='DM SURAT'!J17 -> 9.0737242 | I18: ='DM SURAT'!K17 -> 0 | J18: ='DM SURAT'!L17 -> 0
B20: RM AHMEDABAD | C20: ='RM - NARESH'!E17 -> 26.393762 | D20: ='RM - NARESH'!F17 -> 35.602024 | E20: ='RM - NARESH'!G17 -> 5.8869149 | F20: ='RM - NARESH'!H17 -> 7.6019522 | G20: ='RM - NARESH'!I17 -> 12.57937 | H20: ='RM - NARESH'!J17 -> 21.73603 | I20: ='RM - NARESH'!K17 -> 0.6481008 | J20: ='RM - NARESH'!L17 -> 1.7580471
I23: =E8-G8 -> -6.9846222
I24: =E14-G14 -> 0
I25: =E18-G18 -> 0.2921674
I26: =SUM(I23:I25) -> -6.6924548

Sheet SEC SALES
B2: APRIL 2023-24 | D2: AHMEDABAD POOL | H2: MEHSANA | L2: DM AHMEDABAD | P2: RAJKOT | T2: JUNAGADH | X2: BHAVNAGAR | AB2: BHUJ | AF2: DM RAJKOT | AJ2: SURAT POOL | AN2: BARODA POOL | AR2: DM SURAT | AV2: RM AHMEDABAD
A3: S.No | B3: PRODUCT | C3: Billing Price 23-24 | D3: SEC | E3: CLG | F3: GIT | G3: TOT. CLG. WITH GIT | H3: SEC | I3: CLG | J3: GIT | K3: TOT. CLG. WITH GIT | L3: SEC | M3: CLG | N3: GIT | O3: TOT. CLG. WITH GIT | P3: SEC | Q3: CLG | R3: GIT | S3: TOT. CLG. WITH GIT | T3: SEC | U3: CLG | V3: GIT | W3: TOT. CLG. WITH GIT | X3: SEC | Y3: CLG | Z3: GIT | AA3: TOT. CLG. WITH GIT | AB3: SEC | AC3: CLG | AD3: GIT | AE3: TOT. CLG. WITH GIT | AF3: SEC | AG3: CLG | AH3: GIT | AI3: TOT. CLG. WITH GIT | AJ3: SEC | AK3: CLG | AL3: GIT | AM3: TOT. CLG. WITH GIT | AN3: SEC | AO3: CLG | AP3: GIT | AQ3: TOT. CLG. WITH GIT | AR3: SEC | AS3: CLG | AT3: GIT | AU3: TOT. CLG. WITH GIT | AV3: SEC | AW3: CLG | AX3: GIT | AY3: TOT. CLG. WITH GIT
A4: 1 | B4: HUMYL MILK MASALA 200 GM | C4: 183.05 | D4: =AHMEDABAD!E4 -> 5 | E4: =AHMEDABAD!F4 -> 63 | F4: 0 | G4: =E4 -> 63 | H4: =MEHSANA!E4 -> 29 | I4: =MEHSANA!F4 -> 60 | J4: 0 | K4: =I4 -> 60 | L4: ='DM ABAD'!E3 -> 9 | M4: ='DM ABAD'!F3 -> 105 | N4: 0 | O4: =M4 -> 105 | P4: =RAJKOT!E3 -> 19 | Q4: =RAJKOT!F3 -> 50 | R4: 0 | S4: =Q4 -> 50 | T4: =JUNAGADH!E4 -> 200 | U4: =JUNAGADH!F4 -> 163 | V4: 0 | W4: =U4 -> 163 | X4: =BHAVNAGAR!E4 -> 0 | Y4: =BHAVNAGAR!F4 -> 24 | Z4: 0 | AA4: =Y4 -> 24 | AB4: =BHUJ!E4 -> 32 | AC4: =BHUJ!F4 -> 166 | AD4: 0 | AE4: =AC4 -> 166 | AF4: ='DM RAJKOT'!E3 -> 34 | AG4: ='DM RAJKOT'!F3 -> 124 | AH4: 0 | AI4: =AG4 -> 124 | AJ4: =SURAT!E4 -> 79 | AK4: =SURAT!F4 -> 188 | AL4: 0 | AM4: =AK4 -> 188 | AN4: =BARODA!E4 -> 195 | AO4: =BARODA!F4 -> 178 | AP4: 0 | AQ4: =AO4 -> 178 | AR4: ='DM SURAT'!E3 -> 63 | AS4: ='DM SURAT'!F3 -> 98 | AT4: 0 | AU4: =AS4 -> 98 | AV4: ='RM - NARESH'!E3 -> 106 | AW4: ='RM - NARESH'!F3 -> 327 | AX4: 0 | AY4: =AW4 -> 327
A5: 2 | B5: ZEFRICH CHOCOLATE 200 GM | C5: 198.31 | D5: =AHMEDABAD!E5 -> 100 | E5: =AHMEDABAD!F5 -> 250 | F5: 0 | G5: =E5 -> 250 | H5: =MEHSANA!E5 -> 38 | I5: =MEHSANA!F5 -> 95 | J5: 0 | K5: =I5 -> 95 | L5: ='DM ABAD'!E4 -> 34 | M5: ='DM ABAD'!F4 -> 123 | N5: 0 | O5: =M5 -> 123 | P5: =RAJKOT!E4 -> 77 | Q5: =RAJKOT!F4 -> 48 | R5: 0 | S5: =Q5 -> 48 | T5: =JUNAGADH!E5 -> 187 | U5: =JUNAGADH!F5 -> 221 | V5: 0 | W5: =U5 -> 221 | X5: =BHAVNAGAR!E5 -> 0 | Y5: =BHAVNAGAR!F5 -> 0 | Z5: 0 | AA5: =Y5 -> 0 | AB5: =BHUJ!E5 -> 80 | AC5: =BHUJ!F5 -> 74 | AD5: 0 | AE5: =AC5 -> 74 | AF5: ='DM RAJKOT'!E4 -> 309 | AG5: ='DM RAJKOT'!F4 -> 401 | AH5: 0 | AI5: =AG5 -> 401 | AJ5: =SURAT!E5 -> 212 | AK5: =SURAT!F5 -> 274 | AL5: 0 | AM5: =AK5 -> 274 | AN5: =BARODA!E5 -> 277 | AO5: =BARODA!F5 -> 304 | AP5: 0 | AQ5: =AO5 -> 304 | AR5: ='DM SURAT'!E4 -> 274 | AS5: ='DM SURAT'!F4 -> 366 | AT5: 0 | AU5: =AS5 -> 366 | AV5: ='RM - NARESH'!E4 -> 617 | AW5: ='RM - NARESH'!F4 -> 890 | AX5: 0 | AY5: =AW5 -> 890
A6: 3 | B6: ZEFRICH MILK MASALA 200 GM | C6: 198.31 | D6: =AHMEDABAD!E6 -> 95 | E6: =AHMEDABAD!F6 -> 238 | F6: 0 | G6: =E6 -> 238 | H6: =MEHSANA!E6 -> 0 | I6: =MEHSANA!F6 -> 8 | J6: 0 | K6: =I6 -> 8 | L6: ='DM ABAD'!E5 -> 138 | M6: ='DM ABAD'!F5 -> 345 | N6: 0 | O6: =M6 -> 345 | P6: =RAJKOT!E5 -> 173 | Q6: =RAJKOT!F5 -> 77 | R6: 0 | S6: =Q6 -> 77 | T6: =JUNAGADH!E6 -> 159 | U6: =JUNAGADH!F6 -> 162 | V6: 0 | W6: =U6 -> 162 | X6: =BHAVNAGAR!E6 -> 0 | Y6: =BHAVNAGAR!F6 -> 0 | Z6: 0 | AA6: =Y6 -> 0 | AB6: =BHUJ!E6 -> 39 | AC6: =BHUJ!F6 -> 74 | AD6: 0 | AE6: =AC6 -> 74 | AF6: ='DM RAJKOT'!E5 -> 440 | AG6: ='DM RAJKOT'!F5 -> 372 | AH6: 0 | AI6: =AG6 -> 372 | AJ6: =SURAT!E6 -> 135 | AK6: =SURAT!F6 -> 244 | AL6: 0 | AM6: =AK6 -> 244 | AN6: =BARODA!E6 -> 188 | AO6: =BARODA!F6 -> 172 | AP6: 0 | AQ6: =AO6 -> 172 | AR6: ='DM SURAT'!E5 -> 489 | AS6: ='DM SURAT'!F5 -> 578 | AT6: 0 | AU6: =AS6 -> 578 | AV6: ='RM - NARESH'!E5 -> 1067 | AW6: ='RM - NARESH'!F5 -> 1295 | AX6: 0 | AY6: =AW6 -> 1295
A7: 4 | B7: SIMYL MCT OIL (HDPE) 100 ML | C7: 180 | D7: =AHMEDABAD!E7 -> 260 | E7: =AHMEDABAD!F7 -> 427 | F7: 0 | G7: =E7 -> 427 | H7: =MEHSANA!E7 -> 286 | I7: =MEHSANA!F7 -> 175 | J7: 0 | K7: =I7 -> 175 | L7: ='DM ABAD'!E6 -> 95 | M7: ='DM ABAD'!F6 -> 246 | N7: 0 | O7: =M7 -> 246 | P7: =RAJKOT!E6 -> 101 | Q7: =RAJKOT!F6 -> 84 | R7: 0 | S7: =Q7 -> 84 | T7: =JUNAGADH!E7 -> 33 | U7: =JUNAGADH!F7 -> 115 | V7: 0 | W7: =U7 -> 115 | X7: =BHAVNAGAR!E7 -> 11 | Y7: =BHAVNAGAR!F7 -> 22 | Z7: 0 | AA7: =Y7 -> 22 | AB7: =BHUJ!E7 -> 6 | AC7: =BHUJ!F7 -> 23 | AD7: 0 | AE7: =AC7 -> 23 | AF7: ='DM RAJKOT'!E6 -> 299 | AG7: ='DM RAJKOT'!F6 -> 320 | AH7: 0 | AI7: =AG7 -> 320 | AJ7: =SURAT!E7 -> 94 | AK7: =SURAT!F7 -> 277 | AL7: 0 | AM7: =AK7 -> 277 | AN7: =BARODA!E7 -> 215 | AO7: =BARODA!F7 -> 320 | AP7: 0 | AQ7: =AO7 -> 320 | AR7: ='DM SURAT'!E6 -> 323 | AS7: ='DM SURAT'!F6 -> 416 | AT7: 0 | AU7: =AS7 -> 416 | AV7: ='RM - NARESH'!E6 -> 717 | AW7: ='RM - NARESH'!F6 -> 982 | AX7: 0 | AY7: =AW7 -> 982
A8: 5 | B8: SIMYL MCT 200 GM | C8: 167.8 | D8: =AHMEDABAD!E8 -> 397 | E8: =AHMEDABAD!F8 -> 420 | F8: 0 | G8: =E8 -> 420 | H8: =MEHSANA!E8 -> 116 | I8: =MEHSANA!F8 -> 89 | J8: 0 | K8: =I8 -> 89 | L8: ='DM ABAD'!E7 -> 546 | M8: ='DM ABAD'!F7 -> 602 | N8: 0 | O8: =M8 -> 602 | P8: =RAJKOT!E7 -> 34 | Q8: =RAJKOT!F7 -> 51 | R8: 0 | S8: =Q8 -> 51 | T8: =JUNAGADH!E8 -> 3 | U8: =JUNAGADH!F8 -> 21 | V8: 0 | W8: =U8 -> 21 | X8: =BHAVNAGAR!E8 -> 14 | Y8: =BHAVNAGAR!F8 -> 47 | Z8: 0 | AA8: =Y8 -> 47 | AB8: =BHUJ!E8 -> 0 | AC8: =BHUJ!F8 -> 0 | AD8: 0 | AE8: =AC8 -> 0 | AF8: ='DM RAJKOT'!E7 -> 84 | AG8: ='DM RAJKOT'!F7 -> 211 | AH8: 0 | AI8: =AG8 -> 211 | AJ8: =SURAT!E8 -> 181 | AK8: =SURAT!F8 -> 328 | AL8: 0 | AM8: =AK8 -> 328 | AN8: =BARODA!E8 -> 139 | AO8: =BARODA!F8 -> 241 | AP8: 0 | AQ8: =AO8 -> 241 | AR8: ='DM SURAT'!E7 -> 309 | AS8: ='DM SURAT'!F7 -> 597 | AT8: 0 | AU8: =AS8 -> 597 | AV8: ='RM - NARESH'!E7 -> 939 | AW8: ='RM - NARESH'!F7 -> 1410 | AX8: 0 | AY8: =AW8 -> 1410
A9: 6 | B9: SIMYL MCT 400 GM | C9: 311.19 | D9: =AHMEDABAD!E9 -> 843 | E9: =AHMEDABAD!F9 -> 857 | F9: 0 | G9: =E9 -> 857 | H9: =MEHSANA!E9 -> 299 | I9: =MEHSANA!F9 -> 234 | J9: 0 | K9: =I9 -> 234 | L9: ='DM ABAD'!E8 -> 513 | M9: ='DM ABAD'!F8 -> 509 | N9: 0 | O9: =M9 -> 509 | P9: =RAJKOT!E8 -> 37 | Q9: =RAJKOT!F8 -> 75 | R9: 0 | S9: =Q9 -> 75 | T9: =JUNAGADH!E9 -> 555 | U9: =JUNAGADH!F9 -> 515 | V9: 0 | W9: =U9 -> 515 | X9: =BHAVNAGAR!E9 -> 127 | Y9: =BHAVNAGAR!F9 -> 152 | Z9: 0 | AA9: =Y9 -> 152 | AB9: =BHUJ!E9 -> 47 | AC9: =BHUJ!F9 -> 24 | AD9: 0 | AE9: =AC9 -> 24 | AF9: ='DM RAJKOT'!E8 -> 54 | AG9: ='DM RAJKOT'!F8 -> 143 | AH9: 0 | AI9: =AG9 -> 143 | AJ9: =SURAT!E9 -> 1009 | AK9: =SURAT!F9 -> 1262 | AL9: 0 | AM9: =AK9 -> 1262 | AN9: =BARODA!E9 -> 983 | AO9: =BARODA!F9 -> 901 | AP9: 0 | AQ9: =AO9 -> 901 | AR9: ='DM SURAT'!E8 -> 320 | AS9: ='DM SURAT'!F8 -> 569 | AT9: 0 | AU9: =AS9 -> 569 | AV9: ='RM - NARESH'!E8 -> 887 | AW9: ='RM - NARESH'!F8 -> 1221 | AX9: 0 | AY9: =AW9 -> 1221
A10: 7 | B10: SIMYL-LBW 400 GM | C10: 305.08 | D10: =AHMEDABAD!E10 -> 41 | E10: =AHMEDABAD!F10 -> 103 | F10: 0 | G10: =E10 -> 103 | H10: =MEHSANA!E10 -> 21 | I10: =MEHSANA!F10 -> 57 | J10: 0 | K10: =I10 -> 57 | L10: ='DM ABAD'!E9 -> 1142 | M10: ='DM ABAD'!F9 -> 1091 | N10: 0 | O10: =M10 -> 1091 | P10: =RAJKOT!E9 -> 542 | Q10: =RAJKOT!F9 -> 287 | R10: 0 | S10: =Q10 -> 287 | T10: =JUNAGADH!E10 -> 52 | U10: =JUNAGADH!F10 -> 75 | V10: 0 | W10: =U10 -> 75 | X10: =BHAVNAGAR!E10 -> 6 | Y10: =BHAVNAGAR!F10 -> 11 | Z10: 0 | AA10: =Y10 -> 11 | AB10: =BHUJ!E10 -> 0 | AC10: =BHUJ!F10 -> 18 | AD10: 0 | AE10: =AC10 -> 18 | AF10: ='DM RAJKOT'!E9 -> 1271 | AG10: ='DM RAJKOT'!F9 -> 978 | AH10: 0 | AI10: =AG10 -> 978 | AJ10: =SURAT!E10 -> 0 | AK10: =SURAT!F10 -> 68 | AL10: 0 | AM10: =AK10 -> 68 | AN10: =BARODA!E10 -> 40 | AO10: =BARODA!F10 -> 76 | AP10: 0 | AQ10: =AO10 -> 76 | AR10: ='DM SURAT'!E9 -> 1992 | AS10: ='DM SURAT'!F9 -> 2163 | AT10: 0 | AU10: =AS10 -> 2163 | AV10: ='RM - NARESH'!E9 -> 4405 | AW10: ='RM - NARESH'!F9 -> 4232 | AX10: 0 | AY10: =AW10 -> 4232
A11: 8 | B11: MUMMUM-1 400 GM | C11: 234.92 | D11: =AHMEDABAD!E11 -> 123 | E11: =AHMEDABAD!F11 -> 276 | F11: 0 | G11: =E11 -> 276 | H11: =MEHSANA!E11 -> 27 | I11: =MEHSANA!F11 -> 61 | J11: 0 | K11: =I11 -> 61 | L11: ='DM ABAD'!E10 -> 62 | M11: ='DM ABAD'!F10 -> 160 | N11: 0 | O11: =M11 -> 160 | P11: =RAJKOT!E10 -> 11 | Q11: =RAJKOT!F10 -> 38 | R11: 0 | S11: =Q11 -> 38 | T11: =JUNAGADH!E11 -> 9 | U11: =JUNAGADH!F11 -> 42 | V11: 0 | W11: =U11 -> 42 | X11: =BHAVNAGAR!E11 -> 1 | Y11: =BHAVNAGAR!F11 -> 31 | Z11: 0 | AA11: =Y11 -> 31 | AB11: =BHUJ!E11 -> 14 | AC11: =BHUJ!F11 -> 42 | AD11: 0 | AE11: =AC11 -> 42 | AF11: ='DM RAJKOT'!E10 -> 69 | AG11: ='DM RAJKOT'!F10 -> 142 | AH11: 0 | AI11: =AG11 -> 142 | AJ11: =SURAT!E11 -> 78 | AK11: =SURAT!F11 -> 193 | AL11: 0 | AM11: =AK11 -> 193 | AN11: =BARODA!E11 -> 69 | AO11: =BARODA!F11 -> 210 | AP11: 0 | AQ11: =AO11 -> 210 | AR11: ='DM SURAT'!E10 -> 40 | AS11: ='DM SURAT'!F10 -> 144 | AT11: 0 | AU11: =AS11 -> 144 | AV11: ='RM - NARESH'!E10 -> 171 | AW11: ='RM - NARESH'!F10 -> 446 | AX11: 0 | AY11: =AW11 -> 446
A12: 9 | B12: MUMMUM-2 400 GM | C12: 234.92 | D12: =AHMEDABAD!E12 -> 64 | E12: =AHMEDABAD!F12 -> 183 | F12: 0 | G12: =E12 -> 183 | H12: =MEHSANA!E12 -> 12 | I12: =MEHSANA!F12 -> 75 | J12: 0 | K12: =I12 -> 75 | L12: ='DM ABAD'!E11 -> 150 | M12: ='DM ABAD'!F11 -> 337 | N12: 0 | O12: =M12 -> 337 | P12: =RAJKOT!E11 -> 28 | Q12: =RAJKOT!F11 -> 88 | R12: 0 | S12: =Q12 -> 88 | T12: =JUNAGADH!E12 -> 27 | U12: =JUNAGADH!F12 -> 48 | V12: 0 | W12: =U12 -> 48 | X12: =BHAVNAGAR!E12 -> 0 | Y12: =BHAVNAGAR!F12 -> 97 | Z12: 0 | AA12: =Y12 -> 97 | AB12: =BHUJ!E12 -> 10 | AC12: =BHUJ!F12 -> 24 | AD12: 0 | AE12: =AC12 -> 24 | AF12: ='DM RAJKOT'!E11 -> 52 | AG12: ='DM RAJKOT'!F11 -> 203 | AH12: 0 | AI12: =AG12 -> 203 | AJ12: =SURAT!E12 -> 60 | AK12: =SURAT!F12 -> 183 | AL12: 0 | AM12: =AK12 -> 183 | AN12: =BARODA!E12 -> 10 | AO12: =BARODA!F12 -> 76 | AP12: 0 | AQ12: =AO12 -> 76 | AR12: ='DM SURAT'!E11 -> 147 | AS12: ='DM SURAT'!F11 -> 403 | AT12: 0 | AU12: =AS12 -> 403 | AV12: ='RM - NARESH'!E11 -> 349 | AW12: ='RM - NARESH'!F11 -> 943 | AX12: 0 | AY12: =AW12 -> 943
A13: 10 | B13: ZIORAL ORAL SOLUTION 100 ML | C13: 57.99 | D13: =AHMEDABAD!E13 -> 10 | E13: =AHMEDABAD!F13 -> 58 | F13: 0 | G13: =E13 -> 58 | H13: =MEHSANA!E13 -> 3 | I13: =MEHSANA!F13 -> 19 | J13: 0 | K13: =I13 -> 19 | L13: ='DM ABAD'!E12 -> 76 | M13: ='DM ABAD'!F12 -> 258 | N13: 0 | O13: =M13 -> 258 | P13: =RAJKOT!E12 -> 36 | Q13: =RAJKOT!F12 -> 64 | R13: 0 | S13: =Q13 -> 64 | T13: =JUNAGADH!E13 -> 24 | U13: =JUNAGADH!F13 -> 44 | V13: 0 | W13: =U13 -> 44 | X13: =BHAVNAGAR!E13 -> 0 | Y13: =BHAVNAGAR!F13 -> 4 | Z13: 0 | AA13: =Y13 -> 4 | AB13: =BHUJ!E13 -> 1 | AC13: =BHUJ!F13 -> 9 | AD13: 0 | AE13: =AC13 -> 9 | AF13: ='DM RAJKOT'!E12 -> 73 | AG13: ='DM RAJKOT'!F12 -> 233 | AH13: 0 | AI13: =AG13 -> 233 | AJ13: =SURAT!E13 -> 11 | AK13: =SURAT!F13 -> 17 | AL13: 0 | AM13: =AK13 -> 17 | AN13: =BARODA!E13 -> 7 | AO13: =BARODA!F13 -> 18 | AP13: 0 | AQ13: =AO13 -> 18 | AR13: ='DM SURAT'!E12 -> 70 | AS13: ='DM SURAT'!F12 -> 259 | AT13: 0 | AU13: =AS13 -> 259 | AV13: ='RM - NARESH'!E12 -> 219 | AW13: ='RM - NARESH'!F12 -> 750 | AX13: 0 | AY13: =AW13 -> 750
A14: 11 | B14: ZIORAL DROPS 15 ML | C14: 46.67 | D14: =AHMEDABAD!E14 -> 248 | E14: =AHMEDABAD!F14 -> 361 | F14: 0 | G14: =E14 -> 361 | H14: =MEHSANA!E14 -> 338 | I14: =MEHSANA!F14 -> 403 | J14: 0 | K14: =I14 -> 403 | L14: ='DM ABAD'!E13 -> 13 | M14: ='DM ABAD'!F13 -> 77 | N14: 0 | O14: =M14 -> 77 | P14: =RAJKOT!E13 -> 8 | Q14: =RAJKOT!F13 -> 37 | R14: 0 | S14: =Q14 -> 37 | T14: =JUNAGADH!E14 -> 80 | U14: =JUNAGADH!F14 -> 57 | V14: 0 | W14: =U14 -> 57 | X14: =BHAVNAGAR!E14 -> 12 | Y14: =BHAVNAGAR!F14 -> 101 | Z14: 0 | AA14: =Y14 -> 101 | AB14: =BHUJ!E14 -> 59 | AC14: =BHUJ!F14 -> 116 | AD14: 0 | AE14: =AC14 -> 116 | AF14: ='DM RAJKOT'!E13 -> 33 | AG14: ='DM RAJKOT'!F13 -> 94 | AH14: 0 | AI14: =AG14 -> 94 | AJ14: =SURAT!E14 -> 259 | AK14: =SURAT!F14 -> 333 | AL14: 0 | AM14: =AK14 -> 333 | AN14: =BARODA!E14 -> 353 | AO14: =BARODA!F14 -> 487 | AP14: 0 | AQ14: =AO14 -> 487 | AR14: ='DM SURAT'!E13 -> 18 | AS14: ='DM SURAT'!F13 -> 35 | AT14: 0 | AU14: =AS14 -> 35 | AV14: ='RM - NARESH'!E13 -> 64 | AW14: ='RM - NARESH'!F13 -> 206 | AX14: 0 | AY14: =AW14 -> 206
A15: 12 | B15: ZIORAL TABLETS 15 T | C15: 38.57 | D15: =AHMEDABAD!E15 -> 630 | E15: =AHMEDABAD!F15 -> 586 | F15: 0 | G15: =E15 -> 586 | H15: =MEHSANA!E15 -> 92 | I15: =MEHSANA!F15 -> 219 | J15: 0 | K15: =I15 -> 219 | L15: ='DM ABAD'!E14 -> 586 | M15: ='DM ABAD'!F14 -> 764 | N15: 0 | O15: =M15 -> 764 | P15: =RAJKOT!E14 -> 166 | Q15: =RAJKOT!F14 -> 282 | R15: 0 | S15: =Q15 -> 282 | T15: =JUNAGADH!E15 -> 45 | U15: =JUNAGADH!F15 -> 93 | V15: 0 | W15: =U15 -> 93 | X15: =BHAVNAGAR!E15 -> 62 | Y15: =BHAVNAGAR!F15 -> 174 | Z15: 0 | AA15: =Y15 -> 174 | AB15: =BHUJ!E15 -> 0 | AC15: =BHUJ!F15 -> 65 | AD15: 0 | AE15: =AC15 -> 65 | AF15: ='DM RAJKOT'!E14 -> 317 | AG15: ='DM RAJKOT'!F14 -> 556 | AH15: 0 | AI15: =AG15 -> 556 | AJ15: =SURAT!E15 -> 498 | AK15: =SURAT!F15 -> 553 | AL15: 0 | AM15: =AK15 -> 553 | AN15: =BARODA!E15 -> 282 | AO15: =BARODA!F15 -> 516 | AP15: 0 | AQ15: =AO15 -> 516 | AR15: ='DM SURAT'!E14 -> 612 | AS15: ='DM SURAT'!F14 -> 820 | AT15: 0 | AU15: =AS15 -> 820 | AV15: ='RM - NARESH'!E14 -> 1515 | AW15: ='RM - NARESH'!F14 -> 2140 | AX15: 0 | AY15: =AW15 -> 2140
A16: 13 | B16: CALYUMM P SUSPENSION 200 ML | C16: 84.5 | D16: =AHMEDABAD!E16 -> 0 | E16: =AHMEDABAD!F16 -> 0 | F16: 0 | G16: =E16 -> 0 | H16: =MEHSANA!E16 -> 0 | I16: =MEHSANA!F16 -> 0 | J16: 0 | K16: =I16 -> 0 | L16: ='DM ABAD'!E15 -> 722 | M16: ='DM ABAD'!F15 -> 805 | N16: 0 | O16: =M16 -> 805 | P16: =RAJKOT!E15 -> 38 | Q16: =RAJKOT!F15 -> 158 | R16: 0 | S16: =Q16 -> 158 | T16: =JUNAGADH!E16 -> 0 | U16: =JUNAGADH!F16 -> 0 | V16: 0 | W16: =U16 -> 0 | X16: =BHAVNAGAR!E16 -> 0 | Y16: =BHAVNAGAR!F16 -> 0 | Z16: 0 | AA16: =Y16 -> 0 | AB16: =BHUJ!E16 -> 0 | AC16: =BHUJ!F16 -> 0 | AD16: 0 | AE16: =AC16 -> 0 | AF16: ='DM RAJKOT'!E15 -> 145 | AG16: ='DM RAJKOT'!F15 -> 490 | AH16: 0 | AI16: =AG16 -> 490 | AJ16: =SURAT!E16 -> 0 | AK16: =SURAT!F16 -> 0 | AL16: 0 | AM16: =AK16 -> 0 | AN16: =BARODA!E16 -> 0 | AO16: =BARODA!F16 -> 0 | AP16: 0 | AQ16: =AO16 -> 0 | AR16: ='DM SURAT'!E15 -> 780 | AS16: ='DM SURAT'!F15 -> 1069 | AT16: 0 | AU16: =AS16 -> 1069 | AV16: ='RM - NARESH'!E15 -> 1647 | AW16: ='RM - NARESH'!F15 -> 2364 | AX16: 0 | AY16: =AW16 -> 2364
A17: 14 | B17: ZEFRICH BAN VAN TP 200ML RTD | C17: 48.21 | D17: =AHMEDABAD!E17 -> 5.915783 | E17: =AHMEDABAD!F17 -> 8.5350374 | F17: 0 | G17: =E17 -> 8.5350374 | H17: =MEHSANA!E17 -> 2.3450722 | I17: =MEHSANA!F17 -> 2.6669235 | J17: 0 | K17: =I17 -> 2.6669235 | L17: ='DM ABAD'!E16 -> 0 | M17: ='DM ABAD'!F16 -> 0 | N17: 0 | O17: =M17 -> 0 | P17: =RAJKOT!E16 -> 0 | Q17: =RAJKOT!F16 -> 0 | R17: 0 | S17: =Q17 -> 0 | T17: =JUNAGADH!E17 -> 3.1802901 | U17: =JUNAGADH!F17 -> 3.7234853 | V17: 0 | W17: =U17 -> 3.7234853 | X17: =BHAVNAGAR!E17 -> 0.4491427 | Y17: =BHAVNAGAR!F17 -> 1.1804122 | Z17: 0 | AA17: =Y17 -> 1.1804122 | AB17: =BHUJ!E17 -> 0.6264603 | AC17: =BHUJ!F17 -> 1.1933022 | AD17: 0 | AE17: =AC17 -> 1.1933022 | AF17: ='DM RAJKOT'!E16 -> 0 | AG17: ='DM RAJKOT'!F16 -> 0 | AH17: 0 | AI17: =AG17 -> 0 | AJ17: =SURAT!#REF! -> #REF! | AK17: =SURAT!#REF! -> #REF! | AL17: 0 | AM17: =AK17 -> #REF! | AN17: =BARODA!#REF! -> #REF! | AO17: =BARODA!#REF! -> #REF! | AP17: 0 | AQ17: =AO17 -> #REF! | AR17: ='DM SURAT'!E16 -> 0 | AS17: ='DM SURAT'!F16 -> 0 | AT17: 0 | AU17: =AS17 -> 0 | AV17: ='RM - NARESH'!E16 -> 0 | AW17: ='RM - NARESH'!F16 -> 0 | AX17: 0 | AY17: =AW17 -> 0
A18: 15 | B18: MUM MUM 1 SSP/UNIT DOSE | C18: 121.43 | D18: =AHMEDABAD!E18 -> 0 | E18: =AHMEDABAD!F18 -> 0 | F18: 0 | G18: =E18 -> 0 | H18: =MEHSANA!E18 -> 0 | I18: =MEHSANA!F18 -> 0 | J18: 0 | K18: =I18 -> 0 | L18: #REF! | M18: #REF! | N18: 0 | O18: =M18 -> #REF! | P18: =RAJKOT!E17 -> 2.7773458 | Q18: =RAJKOT!F17 -> 2.5789404 | R18: 0 | S18: =Q18 -> 2.5789404 | T18: =JUNAGADH!E18 -> 0 | U18: =JUNAGADH!F18 -> 0 | V18: 0 | W18: =U18 -> 0 | X18: =BHAVNAGAR!E18 -> 0 | Y18: =BHAVNAGAR!F18 -> 0 | Z18: 0 | AA18: =Y18 -> 0 | AB18: =BHUJ!E18 -> 0 | AC18: =BHUJ!F18 -> 0 | AD18: 0 | AE18: =AC18 -> 0 | AF18: ='DM RAJKOT'!#REF! -> #REF! | AG18: ='DM RAJKOT'!#REF! -> #REF! | AH18: 0 | AI18: =AG18 -> #REF! | AJ18: =SURAT!#REF! -> #REF! | AK18: =SURAT!#REF! -> #REF! | AL18: 0 | AM18: =AK18 -> #REF! | AN18: =BARODA!#REF! -> #REF! | AO18: =BARODA!#REF! -> #REF! | AP18: 0 | AQ18: =AO18 -> #REF! | AR18: ='DM SURAT'!#REF! -> #REF! | AS18: ='DM SURAT'!#REF! -> #REF! | AT18: 0 | AU18: =AS18 -> #REF! | AV18: ='RM - NARESH'!#REF! -> #REF! | AW18: ='RM - NARESH'!#REF! -> #REF! | AX18: 0 | AY18: =AW18 -> #REF!
A19: 16 | B19: R5 IMMUNITY DRINK 200 ML | C19: 22.5 | D19: =AHMEDABAD!E19 -> S.S. | E19: =AHMEDABAD!F19 -> C.S. | F19: 0 | G19: =E19 -> C.S. | H19: =MEHSANA!E19 -> S.S. | I19: =MEHSANA!F19 -> C.S. | J19: 0 | K19: =I19 -> C.S. | L19: #REF! | M19: #REF! | N19: 0 | O19: =M19 -> #REF! | P19: =RAJKOT!E18 -> 0 | Q19: =RAJKOT!F18 -> 0 | R19: 0 | S19: =Q19 -> 0 | T19: =JUNAGADH!E19 -> S.S. | U19: =JUNAGADH!F19 -> C.S. | V19: 0 | W19: =U19 -> C.S. | X19: =BHAVNAGAR!E19 -> S.S. | Y19: =BHAVNAGAR!F19 -> C.S. | Z19: 0 | AA19: =Y19 -> C.S. | AB19: =BHUJ!E19 -> S.S. | AC19: =BHUJ!F19 -> C.S. | AD19: 0 | AE19: =AC19 -> C.S. | AF19: ='DM RAJKOT'!#REF! -> #REF! | AG19: ='DM RAJKOT'!#REF! -> #REF! | AH19: 0 | AI19: =AG19 -> #REF! | AJ19: =SURAT!#REF! -> #REF! | AK19: =SURAT!#REF! -> #REF! | AL19: 0 | AM19: =AK19 -> #REF! | AN19: =BARODA!#REF! -> #REF! | AO19: =BARODA!#REF! -> #REF! | AP19: 0 | AQ19: =AO19 -> #REF! | AR19: ='DM SURAT'!#REF! -> #REF! | AS19: ='DM SURAT'!#REF! -> #REF! | AT19: 0 | AU19: =AS19 -> #REF! | AV19: ='RM - NARESH'!#REF! -> #REF! | AW19: ='RM - NARESH'!#REF! -> #REF! | AX19: 0 | AY19: =AW19 -> #REF!
A20: 17
A21: 18
A22: 19
A23: 20
B24: Total | D24: =AHMEDABAD!E24 -> 5.3340786 | E24: =AHMEDABAD!F24 -> 7.9204852 | F24: 0 | G24: =E24 -> 7.9204852 | H24: =SUMPRODUCT($C4:$C23,H4:H23)/100000 -> 2.1201333 | I24: =SUMPRODUCT($C4:$C23,I4:I23)/100000 -> 2.2848549 | J24: =SUMPRODUCT($C4:$C23,J4:J23)/100000 -> 0 | K24: =SUMPRODUCT($C4:$C23,K4:K23)/100000 -> 2.2848549 | P24: =SUMPRODUCT($C4:$C23,P4:P23)/100000 -> 2.7538179 | Q24: =SUMPRODUCT($C4:$C23,Q4:Q23)/100000 -> 2.2809523 | R24: =SUMPRODUCT($C4:$C23,R4:R23)/100000 -> 0 | S24: =SUMPRODUCT($C4:$C23,S4:S23)/100000 -> 2.2809523 | T24: =SUMPRODUCT($C4:$C23,T4:T23)/100000 -> 3.1571472 | U24: =SUMPRODUCT($C4:$C23,U4:U23)/100000 -> 3.432786 | V24: =SUMPRODUCT($C4:$C23,V4:V23)/100000 -> 0 | W24: =SUMPRODUCT($C4:$C23,W4:W23)/100000 -> 3.432786 | ... AE24: =SUMPRODUCT($C4:$C23,AE4:AE23)/100000 -> 1.0084111 | AJ24: =SUMPRODUCT($C4:$C23,AJ4:AJ23)/100000 -> #REF! | AK24: =SUMPRODUCT($C4:$C23,AK4:AK23)/100000 -> #REF! | AL24: =SUMPRODUCT($C4:$C23,AL4:AL23)/100000 -> 0 | AM24: =SUMPRODUCT($C4:$C23,AM4:AM23)/100000 -> #REF! | AN24: =SUMPRODUCT($C4:$C23,AN4:AN23)/100000 -> #REF! | AO24: =SUMPRODUCT($C4:$C23,AO4:AO23)/100000 -> #REF! | AP24: =SUMPRODUCT($C4:$C23,AP4:AP23)/100000 -> 0 | AQ24: =SUMPRODUCT($C4:$C23,AQ4:AQ23)/100000 -> #REF! | ... AY24: =SUMPRODUCT($C4:$C23,AY4:AY23)/100000 -> #REF!
B26: MAY 2023-24 | D26: AHMEDABAD POOL | H26: MEHSANA | L26: DM AHMEDABAD | P26: RAJKOT | T26: JUNAGADH | X26: BHAVNAGAR | AB26: BHUJ | AF26: DM RAJKOT | AJ26: SURAT POOL | AN26: BARODA POOL | AR26: DM SURAT | AV26: RM AHMEDABAD
A27: S.No | B27: PRODUCT | C27: Billing Price 23-24 | D27: SEC | E27: CLG | F27: GIT | G27: TOT. CLG. WITH GIT | H27: SEC | I27: CLG | J27: GIT | K27: TOT. CLG. WITH GIT | L27: SEC | M27: CLG | N27: GIT | O27: TOT. CLG. WITH GIT | P27: SEC | Q27: CLG | R27: GIT | S27: TOT. CLG. WITH GIT | T27: SEC | U27: CLG | V27: GIT | W27: TOT. CLG. WITH GIT | X27: SEC | Y27: CLG | Z27: GIT | AA27: TOT. CLG. WITH GIT | AB27: SEC | AC27: CLG | AD27: GIT | AE27: TOT. CLG. WITH GIT | AF27: SEC | AG27: CLG | AH27: GIT | AI27: TOT. CLG. WITH GIT | AJ27: SEC | AK27: CLG | AL27: GIT | AM27: TOT. CLG. WITH GIT | AN27: SEC | AO27: CLG | AP27: GIT | AQ27: TOT. CLG. WITH GIT | AR27: SEC | AS27: CLG | AT27: GIT | AU27: TOT. CLG. WITH GIT | AV27: SEC | AW27: CLG | AX27: GIT | AY27: TOT. CLG. WITH GIT
A28: 1 | B28: HUMYL MILK MASALA 200 GM | C28: 183.05
A29: 2 | B29: ZEFRICH CHOCOLATE 200 GM | C29: 198.31
A30: 3 | B30: ZEFRICH MILK MASALA 200 GM | C30: 198.31
A31: 4 | B31: SIMYL MCT OIL (HDPE) 100 ML | C31: 180
A32: 5 | B32: SIMYL MCT 200 GM | C32: 167.8
A33: 6 | B33: SIMYL MCT 400 GM | C33: 311.19
A34: 7 | B34: SIMYL-LBW 400 GM | C34: 305.08
A35: 8 | B35: MUMMUM-1 400 GM | C35: 234.92
A36: 9 | B36: MUMMUM-2 400 GM | C36: 234.92
A37: 10 | B37: ZIORAL ORAL SOLUTION 100 ML | C37: 57.99
A38: 11 | B38: ZIORAL DROPS 15 ML | C38: 46.67
A39: 12 | B39: ZIORAL TABLETS 15 T | C39: 38.57
... A43: 16 | B43: R5 IMMUNITY DRINK 200 ML | C43: 22.5
A44: 17
A45: 18
...

Sheet RM - NARESH
A1: 2026_27 | C1: AHMEDABAD - RM | E1: APR'26 | G1: MAY'26 | I1: JUN'26 | K1: JUL'26 | M1: AUG'26 | O1: SEP'26 | Q1: OCT'26 | S1: NOV'26 | U1: DEC'26 | W1: JAN'26 | Y1: FEB'26 | AA1: MAR'26
B2: S.No | C2: PRODUCT | D2: PTS | E2: S.S. | F2: C.S. | G2: S.S. | H2: C.S. | I2: S.S. | J2: C.S. | K2: S.S. | L2: C.S. | M2: S.S. | N2: C.S. | O2: S.S. | P2: C.S. | Q2: S.S. | R2: C.S. | S2: S.S. | T2: C.S. | U2: S.S. | V2: C.S. | W2: S.S. | X2: C.S. | Y2: S.S. | Z2: C.S. | AA2: S.S. | AB2: C.S.
A3: Total Sales | B3: 1 | C3: CALYUMM P SUP 200 ML | D3: 92.9 | E3: ='DM ABAD'!E3+'DM RAJKOT'!E3+'DM SURAT'!E3 -> 106 | F3: ='DM ABAD'!F3+'DM RAJKOT'!F3+'DM SURAT'!F3 -> 327 | G3: ='DM ABAD'!G3+'DM RAJKOT'!G3+'DM SURAT'!G3 -> 45 | H3: ='DM ABAD'!H3+'DM RAJKOT'!H3+'DM SURAT'!H3 -> 101 | I3: ='DM ABAD'!I3+'DM RAJKOT'!I3+'DM SURAT'!I3 -> 95 | J3: ='DM ABAD'!J3+'DM RAJKOT'!J3+'DM SURAT'!J3 -> 373 | K3: ='DM ABAD'!K3+'DM RAJKOT'!K3+'DM SURAT'!K3 -> 2 | L3: ='DM ABAD'!L3+'DM RAJKOT'!L3+'DM SURAT'!L3 -> 7 | ... AB3: ='DM ABAD'!AB3+'DM RAJKOT'!AB3+'DM SURAT'!AB3 -> 0
B4: 2 | C4: MUMMUM-1 200 GM | D4: 154.38 | E4: ='DM ABAD'!E4+'DM RAJKOT'!E4+'DM SURAT'!E4 -> 617 | F4: ='DM ABAD'!F4+'DM RAJKOT'!F4+'DM SURAT'!F4 -> 890 | G4: ='DM ABAD'!G4+'DM RAJKOT'!G4+'DM SURAT'!G4 -> 166 | H4: ='DM ABAD'!H4+'DM RAJKOT'!H4+'DM SURAT'!H4 -> 217 | I4: ='DM ABAD'!I4+'DM RAJKOT'!I4+'DM SURAT'!I4 -> 179 | J4: ='DM ABAD'!J4+'DM RAJKOT'!J4+'DM SURAT'!J4 -> 411 | K4: ='DM ABAD'!K4+'DM RAJKOT'!K4+'DM SURAT'!K4 -> 0 | L4: ='DM ABAD'!L4+'DM RAJKOT'!L4+'DM SURAT'!L4 -> 0 | ... AB4: ='DM ABAD'!AB4+'DM RAJKOT'!AB4+'DM SURAT'!AB4 -> 0
B5: 3 | C5: MUMMUM-1 400 GM | D5: 283.73 | E5: ='DM ABAD'!E5+'DM RAJKOT'!E5+'DM SURAT'!E5 -> 1067 | F5: ='DM ABAD'!F5+'DM RAJKOT'!F5+'DM SURAT'!F5 -> 1295 | G5: ='DM ABAD'!G5+'DM RAJKOT'!G5+'DM SURAT'!G5 -> 344 | H5: ='DM ABAD'!H5+'DM RAJKOT'!H5+'DM SURAT'!H5 -> 265 | I5: ='DM ABAD'!I5+'DM RAJKOT'!I5+'DM SURAT'!I5 -> 379 | J5: ='DM ABAD'!J5+'DM RAJKOT'!J5+'DM SURAT'!J5 -> 665 | K5: ='DM ABAD'!K5+'DM RAJKOT'!K5+'DM SURAT'!K5 -> 7 | L5: ='DM ABAD'!L5+'DM RAJKOT'!L5+'DM SURAT'!L5 -> 36 | ... AB5: ='DM ABAD'!AB5+'DM RAJKOT'!AB5+'DM SURAT'!AB5 -> 0
B6: 4 | C6: MUMMUM-2 400 GM | D6: 344.75 | E6: ='DM ABAD'!E6+'DM RAJKOT'!E6+'DM SURAT'!E6 -> 717 | F6: ='DM ABAD'!F6+'DM RAJKOT'!F6+'DM SURAT'!F6 -> 982 | G6: ='DM ABAD'!G6+'DM RAJKOT'!G6+'DM SURAT'!G6 -> 165 | H6: ='DM ABAD'!H6+'DM RAJKOT'!H6+'DM SURAT'!H6 -> 200 | I6: ='DM ABAD'!I6+'DM RAJKOT'!I6+'DM SURAT'!I6 -> 181 | J6: ='DM ABAD'!J6+'DM RAJKOT'!J6+'DM SURAT'!J6 -> 448 | K6: ='DM ABAD'!K6+'DM RAJKOT'!K6+'DM SURAT'!K6 -> 17 | L6: ='DM ABAD'!L6+'DM RAJKOT'!L6+'DM SURAT'!L6 -> 40 | ... AB6: ='DM ABAD'!AB6+'DM RAJKOT'!AB6+'DM SURAT'!AB6 -> 0
B7: 5 | C7: SIMYL MCT 200 GM | D7: 208.06 | E7: ='DM ABAD'!E7+'DM RAJKOT'!E7+'DM SURAT'!E7 -> 939 | F7: ='DM ABAD'!F7+'DM RAJKOT'!F7+'DM SURAT'!F7 -> 1410 | G7: ='DM ABAD'!G7+'DM RAJKOT'!G7+'DM SURAT'!G7 -> 232 | H7: ='DM ABAD'!H7+'DM RAJKOT'!H7+'DM SURAT'!H7 -> 301 | I7: ='DM ABAD'!I7+'DM RAJKOT'!I7+'DM SURAT'!I7 -> 716 | J7: ='DM ABAD'!J7+'DM RAJKOT'!J7+'DM SURAT'!J7 -> 1097 | K7: ='DM ABAD'!K7+'DM RAJKOT'!K7+'DM SURAT'!K7 -> 28 | L7: ='DM ABAD'!L7+'DM RAJKOT'!L7+'DM SURAT'!L7 -> 141 | ... AB7: ='DM ABAD'!AB7+'DM RAJKOT'!AB7+'DM SURAT'!AB7 -> 0
B8: 6 | C8: SIMYL MCT 400 GM | D8: 399.65 | E8: ='DM ABAD'!E8+'DM RAJKOT'!E8+'DM SURAT'!E8 -> 887 | F8: ='DM ABAD'!F8+'DM RAJKOT'!F8+'DM SURAT'!F8 -> 1221 | G8: ='DM ABAD'!G8+'DM RAJKOT'!G8+'DM SURAT'!G8 -> 185 | H8: ='DM ABAD'!H8+'DM RAJKOT'!H8+'DM SURAT'!H8 -> 336 | I8: ='DM ABAD'!I8+'DM RAJKOT'!I8+'DM SURAT'!I8 -> 563 | J8: ='DM ABAD'!J8+'DM RAJKOT'!J8+'DM SURAT'!J8 -> 879 | K8: ='DM ABAD'!K8+'DM RAJKOT'!K8+'DM SURAT'!K8 -> 6 | L8: ='DM ABAD'!L8+'DM RAJKOT'!L8+'DM SURAT'!L8 -> 39 | ... AB8: ='DM ABAD'!AB8+'DM RAJKOT'!AB8+'DM SURAT'!AB8 -> 0
B9: 7 | C9: SIMYL MCT OIL (HDPE) 100 ML | D9: 228.82 | E9: ='DM ABAD'!E9+'DM RAJKOT'!E9+'DM SURAT'!E9 -> 4405 | F9: ='DM ABAD'!F9+'DM RAJKOT'!F9+'DM SURAT'!F9 -> 4232 | G9: ='DM ABAD'!G9+'DM RAJKOT'!G9+'DM SURAT'!G9 -> 840 | H9: ='DM ABAD'!H9+'DM RAJKOT'!H9+'DM SURAT'!H9 -> 973 | I9: ='DM ABAD'!I9+'DM RAJKOT'!I9+'DM SURAT'!I9 -> 1814 | J9: ='DM ABAD'!J9+'DM RAJKOT'!J9+'DM SURAT'!J9 -> 2501 | K9: ='DM ABAD'!K9+'DM RAJKOT'!K9+'DM SURAT'!K9 -> 146 | L9: ='DM ABAD'!L9+'DM RAJKOT'!L9+'DM SURAT'!L9 -> 280 | ... AB9: ='DM ABAD'!AB9+'DM RAJKOT'!AB9+'DM SURAT'!AB9 -> 0
B10: 8 | C10: SIMYL-LBW 400 GM | D10: 402.71 | E10: ='DM ABAD'!E10+'DM RAJKOT'!E10+'DM SURAT'!E10 -> 171 | F10: ='DM ABAD'!F10+'DM RAJKOT'!F10+'DM SURAT'!F10 -> 446 | G10: ='DM ABAD'!G10+'DM RAJKOT'!G10+'DM SURAT'!G10 -> 63 | H10: ='DM ABAD'!H10+'DM RAJKOT'!H10+'DM SURAT'!H10 -> 80 | I10: ='DM ABAD'!I10+'DM RAJKOT'!I10+'DM SURAT'!I10 -> 148 | J10: ='DM ABAD'!J10+'DM RAJKOT'!J10+'DM SURAT'!J10 -> 214 | K10: ='DM ABAD'!K10+'DM RAJKOT'!K10+'DM SURAT'!K10 -> 0 | L10: ='DM ABAD'!L10+'DM RAJKOT'!L10+'DM SURAT'!L10 -> 0 | ... AB10: ='DM ABAD'!AB10+'DM RAJKOT'!AB10+'DM SURAT'!AB10 -> 0
B11: 9 | C11: ZEFRICH CHOCOLATE 200 GM | D11: 250.17 | E11: ='DM ABAD'!E11+'DM RAJKOT'!E11+'DM SURAT'!E11 -> 349 | F11: ='DM ABAD'!F11+'DM RAJKOT'!F11+'DM SURAT'!F11 -> 943 | G11: ='DM ABAD'!G11+'DM RAJKOT'!G11+'DM SURAT'!G11 -> 92 | H11: ='DM ABAD'!H11+'DM RAJKOT'!H11+'DM SURAT'!H11 -> 187 | I11: ='DM ABAD'!I11+'DM RAJKOT'!I11+'DM SURAT'!I11 -> 214 | J11: ='DM ABAD'!J11+'DM RAJKOT'!J11+'DM SURAT'!J11 -> 618 | K11: ='DM ABAD'!K11+'DM RAJKOT'!K11+'DM SURAT'!K11 -> 0 | L11: ='DM ABAD'!L11+'DM RAJKOT'!L11+'DM SURAT'!L11 -> 66 | ... AB11: ='DM ABAD'!AB11+'DM RAJKOT'!AB11+'DM SURAT'!AB11 -> 0
B12: 10 | C12: ZEFRICH MILK MASALA 200 GM | D12: 250.17 | E12: ='DM ABAD'!E12+'DM RAJKOT'!E12+'DM SURAT'!E12 -> 219 | F12: ='DM ABAD'!F12+'DM RAJKOT'!F12+'DM SURAT'!F12 -> 750 | G12: ='DM ABAD'!G12+'DM RAJKOT'!G12+'DM SURAT'!G12 -> 6 | H12: ='DM ABAD'!H12+'DM RAJKOT'!H12+'DM SURAT'!H12 -> 70 | I12: ='DM ABAD'!I12+'DM RAJKOT'!I12+'DM SURAT'!I12 -> 96 | J12: ='DM ABAD'!J12+'DM RAJKOT'!J12+'DM SURAT'!J12 -> 316 | K12: ='DM ABAD'!K12+'DM RAJKOT'!K12+'DM SURAT'!K12 -> 0 | L12: ='DM ABAD'!L12+'DM RAJKOT'!L12+'DM SURAT'!L12 -> 0 | ... AB12: ='DM ABAD'!AB12+'DM RAJKOT'!AB12+'DM SURAT'!AB12 -> 0
B13: 11 | C13: ZEFRICH HP M M 200 GM | D13: 228.82 | E13: ='DM ABAD'!E13+'DM RAJKOT'!E13+'DM SURAT'!E13 -> 64 | F13: ='DM ABAD'!F13+'DM RAJKOT'!F13+'DM SURAT'!F13 -> 206 | G13: ='DM ABAD'!G13+'DM RAJKOT'!G13+'DM SURAT'!G13 -> 13 | H13: ='DM ABAD'!H13+'DM RAJKOT'!H13+'DM SURAT'!H13 -> 16 | I13: ='DM ABAD'!I13+'DM RAJKOT'!I13+'DM SURAT'!I13 -> 37 | J13: ='DM ABAD'!J13+'DM RAJKOT'!J13+'DM SURAT'!J13 -> 180 | K13: ='DM ABAD'!K13+'DM RAJKOT'!K13+'DM SURAT'!K13 -> 1 | L13: ='DM ABAD'!L13+'DM RAJKOT'!L13+'DM SURAT'!L13 -> 26 | ... AB13: ='DM ABAD'!AB13+'DM RAJKOT'!AB13+'DM SURAT'!AB13 -> 0
B14: 12 | C14: ZIORAL DROPS 15 ML | D14: 56.38 | E14: ='DM ABAD'!E14+'DM RAJKOT'!E14+'DM SURAT'!E14 -> 1515 | F14: ='DM ABAD'!F14+'DM RAJKOT'!F14+'DM SURAT'!F14 -> 2140 | G14: ='DM ABAD'!G14+'DM RAJKOT'!G14+'DM SURAT'!G14 -> 325 | H14: ='DM ABAD'!H14+'DM RAJKOT'!H14+'DM SURAT'!H14 -> 489 | I14: ='DM ABAD'!I14+'DM RAJKOT'!I14+'DM SURAT'!I14 -> 1059 | J14: ='DM ABAD'!J14+'DM RAJKOT'!J14+'DM SURAT'!J14 -> 1657 | K14: ='DM ABAD'!K14+'DM RAJKOT'!K14+'DM SURAT'!K14 -> 73 | L14: ='DM ABAD'!L14+'DM RAJKOT'!L14+'DM SURAT'!L14 -> 164 | ... AB14: ='DM ABAD'!AB14+'DM RAJKOT'!AB14+'DM SURAT'!AB14 -> 0
B15: 13 | C15: ZIORAL ORAL SYP 100 ML | D15: 70.14 | E15: ='DM ABAD'!E15+'DM RAJKOT'!E15+'DM SURAT'!E15 -> 1647 | F15: ='DM ABAD'!F15+'DM RAJKOT'!F15+'DM SURAT'!F15 -> 2364 | G15: ='DM ABAD'!G15+'DM RAJKOT'!G15+'DM SURAT'!G15 -> 268 | H15: ='DM ABAD'!H15+'DM RAJKOT'!H15+'DM SURAT'!H15 -> 369 | I15: ='DM ABAD'!I15+'DM RAJKOT'!I15+'DM SURAT'!I15 -> 815 | J15: ='DM ABAD'!J15+'DM RAJKOT'!J15+'DM SURAT'!J15 -> 1798 | K15: ='DM ABAD'!K15+'DM RAJKOT'!K15+'DM SURAT'!K15 -> 154 | L15: ='DM ABAD'!L15+'DM RAJKOT'!L15+'DM SURAT'!L15 -> 149 | ... AB15: ='DM ABAD'!AB15+'DM RAJKOT'!AB15+'DM SURAT'!AB15 -> 0
B16: 14 | E16: ='DM ABAD'!E16+'DM RAJKOT'!E16+'DM SURAT'!E16 -> 0 | F16: ='DM ABAD'!F16+'DM RAJKOT'!F16+'DM SURAT'!F16 -> 0 | G16: ='DM ABAD'!G16+'DM RAJKOT'!G16+'DM SURAT'!G16 -> 0 | H16: ='DM ABAD'!H16+'DM RAJKOT'!H16+'DM SURAT'!H16 -> 0 | I16: ='DM ABAD'!I16+'DM RAJKOT'!I16+'DM SURAT'!I16 -> 0 | J16: ='DM ABAD'!J16+'DM RAJKOT'!J16+'DM SURAT'!J16 -> 0 | K16: ='DM ABAD'!K16+'DM RAJKOT'!K16+'DM SURAT'!K16 -> 0 | L16: ='DM ABAD'!L16+'DM RAJKOT'!L16+'DM SURAT'!L16 -> 0 | ... AB16: ='DM ABAD'!AB16+'DM RAJKOT'!AB16+'DM SURAT'!AB16 -> 0
C17: Total | E17: =SUMPRODUCT($D3:$D16,E3:E16)/100000 -> 26.393762 | F17: =SUMPRODUCT($D3:$D16,F3:F16)/100000 -> 35.602024 | G17: =SUMPRODUCT($D3:$D16,G3:G16)/100000 -> 5.8869149 | H17: =SUMPRODUCT($D3:$D16,H3:H16)/100000 -> 7.6019522 | I17: =SUMPRODUCT($D3:$D16,I3:I16)/100000 -> 12.57937 | J17: =SUMPRODUCT($D3:$D16,J3:J16)/100000 -> 21.73603 | K17: =SUMPRODUCT($D3:$D16,K3:K16)/100000 -> 0.6481008 | L17: =SUMPRODUCT($D3:$D16,L3:L16)/100000 -> 1.7580471 | ... AB17: =SUMPRODUCT($D3:$D16,AB3:AB16)/100000 -> 0
B19: CODE | C19: PRODUCT | E19: S.S. | F19: C.S. | G19: S.S. | H19: C.S. | I19: S.S. | J19: C.S. | K19: S.S. | L19: C.S. | M19: S.S. | N19: C.S. | O19: S.S. | P19: C.S. | Q19: S.S. | R19: C.S. | S19: S.S. | T19: C.S. | U19: S.S. | V19: C.S. | W19: S.S. | X19: C.S. | Y19: S.S. | Z19: C.S. | AA19: S.S. | AB19: C.S.
C20: MUMMUM GROUP | E20: =SUMPRODUCT($D$4:$D$5:$D$6,E4:E5:E6)/100000 -> 6.4517812 | F20: =SUMPRODUCT($D$4:$D$5:$D$6,F4:F5:F6)/100000 -> 8.4337305 | G20: =SUMPRODUCT($D$2:$D$3:$D$4,G2:G3:G4)/100000 -> 0.2980758 | H20: =SUMPRODUCT($D$2:$D$3:$D$4,H2:H3:H4)/100000 -> 0.4288336 | I20: =SUMPRODUCT($D$2:$D$3:$D$4,I2:I3:I4)/100000 -> 0.3645952 | J20: =SUMPRODUCT($D$2:$D$3:$D$4,J2:J3:J4)/100000 -> 0.9810188 | K20: =SUMPRODUCT($D$2:$D$3:$D$4,K2:K3:K4)/100000 -> 0.001858 | L20: =SUMPRODUCT($D$2:$D$3:$D$4,L2:L3:L4)/100000 -> 0.006503 | M20: =SUMPRODUCT($D$2:$D$3:$D$4,M2:M3:M4)/100000 -> 0 | N20: =SUMPRODUCT($D$2:$D$3:$D$4,N2:N3:N4)/100000 -> 0 | ... AB20: =SUMPRODUCT($D$2:$D$3:$D$4,AB2:AB3:AB4)/100000 -> 0
C21: SIMYL GROUP | E21: =SUMPRODUCT($D$7:$D$8:$D$9:$D$10,E7:E8:E9:E10)/100000 -> 16.266734 | F21: =SUMPRODUCT($D$7:$D$8:$D$9:$D$10,F7:F8:F9:F10)/100000 -> 19.293121 | G21: =SUMPRODUCT($D$5:$D$6:$D$7:$D$8,G5:G6:G7:G8)/100000 -> 2.7669204 | H21: =SUMPRODUCT($D$5:$D$6:$D$7:$D$8,H5:H6:H7:H8)/100000 -> 3.4104691 | I21: =SUMPRODUCT($D$5:$D$6:$D$7:$D$8,I5:I6:I7:I8)/100000 -> 5.4390733 | J21: =SUMPRODUCT($D$5:$D$6:$D$7:$D$8,J5:J6:J7:J8)/100000 -> 9.2266262 | K21: =SUMPRODUCT($D$5:$D$6:$D$7:$D$8,K5:K6:K7:K8)/100000 -> 0.1607044 | L21: =SUMPRODUCT($D$5:$D$6:$D$7:$D$8,L5:L6:L7:L8)/100000 -> 0.6892709 | M21: =SUMPRODUCT($D$5:$D$6:$D$7:$D$8,M5:M6:M7:M8)/100000 -> 0 | N21: =SUMPRODUCT($D$5:$D$6:$D$7:$D$8,N5:N6:N7:N8)/100000 -> 0 | ... AB21: =SUMPRODUCT($D$5:$D$6:$D$7:$D$8,AB5:AB6:AB7:AB8)/100000 -> 0
C22: ZEFRICH GROUP | E22: =SUMPRODUCT($D$11:$D$12:$D$13,E11:E12:E13)/100000 -> 1.5674104 | F22: =SUMPRODUCT($D$11:$D$12:$D$13,F11:F12:F13)/100000 -> 4.7067473 | G22: =SUMPRODUCT($D$9:$D$10:$D$11,G9:G10:G11)/100000 -> 2.4059517 | H22: =SUMPRODUCT($D$9:$D$10:$D$11,H9:H10:H11)/100000 -> 3.0164045 | I22: =SUMPRODUCT($D$9:$D$10:$D$11,I9:I10:I11)/100000 -> 5.2821694 | J22: =SUMPRODUCT($D$9:$D$10:$D$11,J9:J10:J11)/100000 -> 8.1306382 | K22: =SUMPRODUCT($D$9:$D$10:$D$11,K9:K10:K11)/100000 -> 0.3340772 | L22: =SUMPRODUCT($D$9:$D$10:$D$11,L9:L10:L11)/100000 -> 0.8058082 | M22: =SUMPRODUCT($D$9:$D$10:$D$11,M9:M10:M11)/100000 -> 0 | N22: =SUMPRODUCT($D$9:$D$10:$D$11,N9:N10:N11)/100000 -> 0 | ... AB22: =SUMPRODUCT($D$9:$D$10:$D$11,AB9:AB10:AB11)/100000 -> 0
C23: ZIORAL GROUP | E23: =SUMPRODUCT($D$14:$D$15,E14:E15)/100000 -> 2.0093628 | F23: =SUMPRODUCT($D$14:$D$15,F14:F15)/100000 -> 2.8646416 | G23: =SUMPRODUCT($D$12:$D$13,G12:G13)/100000 -> 0.0447568 | H23: =SUMPRODUCT($D$12:$D$13,H12:H13)/100000 -> 0.2117302 | I23: =SUMPRODUCT($D$12:$D$13,I12:I13)/100000 -> 0.3248266 | J23: =SUMPRODUCT($D$12:$D$13,J12:J13)/100000 -> 1.2024132 | K23: =SUMPRODUCT($D$12:$D$13,K12:K13)/100000 -> 0.0022882 | L23: =SUMPRODUCT($D$12:$D$13,L12:L13)/100000 -> 0.0594932 | M23: =SUMPRODUCT($D$12:$D$13,M12:M13)/100000 -> 0 | N23: =SUMPRODUCT($D$12:$D$13,N12:N13)/100000 -> 0 | ... AB23: =SUMPRODUCT($D$12:$D$13,AB12:AB13)/100000 -> 0
C24: Total | E24: =SUM(E20:E23) -> 26.295288 | F24: =SUM(F20:F23) -> 35.298241 | G24: =SUM(G20:G23) -> 5.5157047 | H24: =SUM(H20:H23) -> 7.0674374 | I24: =SUM(I20:I23) -> 11.410664 | J24: =SUM(J20:J23) -> 19.540696 | K24: =SUM(K20:K23) -> 0.4989278 | L24: =SUM(L20:L23) -> 1.5610753 | ... AB24: =SUM(AB20:AB23) -> 0

Sheet DM ABAD
A1: 2026_27 | C1: MADANLAL - DM AHMEDABAD | E1: APR'26 | G1: MAY'26 | I1: JUN'26 | K1: JUL'26 | M1: AUG'26 | O1: SEP'26 | Q1: OCT'26 | S1: NOV'26 | U1: DEC'26 | W1: JAN'26 | Y1: FEB'26 | AA1: MAR'26
B2: S.No | C2: PRODUCT | D2: PTS | E2: S.S. | F2: C.S. | G2: S.S. | H2: C.S. | I2: S.S. | J2: C.S. | K2: S.S. | L2: C.S. | M2: S.S. | N2: C.S. | O2: S.S. | P2: C.S. | Q2: S.S. | R2: C.S. | S2: S.S. | T2: C.S. | U2: S.S. | V2: C.S. | W2: S.S. | X2: C.S. | Y2: S.S. | Z2: C.S. | AA2: S.S. | AB2: C.S.
A3: Total Sales | B3: 1 | C3: CALYUMM P SUP 200 ML | D3: 92.9 | E3: =AHMEDABAD!E3+MEHSANA!E3 -> 9 | F3: =AHMEDABAD!F3+MEHSANA!F3 -> 105 | G3: =AHMEDABAD!G3+MEHSANA!G3 -> 0 | H3: =AHMEDABAD!H3+MEHSANA!H3 -> 0 | I3: =AHMEDABAD!I3+MEHSANA!I3 -> 22 | J3: =AHMEDABAD!J3+MEHSANA!J3 -> 103 | K3: =AHMEDABAD!K3+MEHSANA!K3 -> 2 | L3: =AHMEDABAD!L3+MEHSANA!L3 -> 7 | ... AB3: =AHMEDABAD!AB3+MEHSANA!AB3 -> 0
B4: 2 | C4: MUMMUM-1 200 GM | D4: 154.38 | E4: =AHMEDABAD!E4+MEHSANA!E4 -> 34 | F4: =AHMEDABAD!F4+MEHSANA!F4 -> 123 | G4: =AHMEDABAD!G4+MEHSANA!G4 -> 0 | H4: =AHMEDABAD!H4+MEHSANA!H4 -> 0 | I4: =AHMEDABAD!I4+MEHSANA!I4 -> 36 | J4: =AHMEDABAD!J4+MEHSANA!J4 -> 186 | K4: =AHMEDABAD!K4+MEHSANA!K4 -> 0 | L4: =AHMEDABAD!L4+MEHSANA!L4 -> 0 | ... AB4: =AHMEDABAD!AB4+MEHSANA!AB4 -> 0
B5: 3 | C5: MUMMUM-1 400 GM | D5: 283.73 | E5: =AHMEDABAD!E5+MEHSANA!E5 -> 138 | F5: =AHMEDABAD!F5+MEHSANA!F5 -> 345 | G5: =AHMEDABAD!G5+MEHSANA!G5 -> 0 | H5: =AHMEDABAD!H5+MEHSANA!H5 -> 0 | I5: =AHMEDABAD!I5+MEHSANA!I5 -> 104 | J5: =AHMEDABAD!J5+MEHSANA!J5 -> 344 | K5: =AHMEDABAD!K5+MEHSANA!K5 -> 7 | L5: =AHMEDABAD!L5+MEHSANA!L5 -> 36 | ... AB5: =AHMEDABAD!AB5+MEHSANA!AB5 -> 0
B6: 4 | C6: MUMMUM-2 400 GM | D6: 344.75 | E6: =AHMEDABAD!E6+MEHSANA!E6 -> 95 | F6: =AHMEDABAD!F6+MEHSANA!F6 -> 246 | G6: =AHMEDABAD!G6+MEHSANA!G6 -> 0 | H6: =AHMEDABAD!H6+MEHSANA!H6 -> 0 | I6: =AHMEDABAD!I6+MEHSANA!I6 -> 45 | J6: =AHMEDABAD!J6+MEHSANA!J6 -> 220 | K6: =AHMEDABAD!K6+MEHSANA!K6 -> 17 | L6: =AHMEDABAD!L6+MEHSANA!L6 -> 40 | ... AB6: =AHMEDABAD!AB6+MEHSANA!AB6 -> 0
B7: 5 | C7: SIMYL MCT 200 GM | D7: 208.06 | E7: =AHMEDABAD!E7+MEHSANA!E7 -> 546 | F7: =AHMEDABAD!F7+MEHSANA!F7 -> 602 | G7: =AHMEDABAD!G7+MEHSANA!G7 -> 0 | H7: =AHMEDABAD!H7+MEHSANA!H7 -> 0 | I7: =AHMEDABAD!I7+MEHSANA!I7 -> 525 | J7: =AHMEDABAD!J7+MEHSANA!J7 -> 697 | K7: =AHMEDABAD!K7+MEHSANA!K7 -> 28 | L7: =AHMEDABAD!L7+MEHSANA!L7 -> 141 | ... AB7: =AHMEDABAD!AB7+MEHSANA!AB7 -> 0
B8: 6 | C8: SIMYL MCT 400 GM | D8: 399.65 | E8: =AHMEDABAD!E8+MEHSANA!E8 -> 513 | F8: =AHMEDABAD!F8+MEHSANA!F8 -> 509 | G8: =AHMEDABAD!G8+MEHSANA!G8 -> 0 | H8: =AHMEDABAD!H8+MEHSANA!H8 -> 0 | I8: =AHMEDABAD!I8+MEHSANA!I8 -> 364 | J8: =AHMEDABAD!J8+MEHSANA!J8 -> 514 | K8: =AHMEDABAD!K8+MEHSANA!K8 -> 6 | L8: =AHMEDABAD!L8+MEHSANA!L8 -> 39 | ... AB8: =AHMEDABAD!AB8+MEHSANA!AB8 -> 0
B9: 7 | C9: SIMYL MCT OIL (HDPE) 100 ML | D9: 228.82 | E9: =AHMEDABAD!E9+MEHSANA!E9 -> 1142 | F9: =AHMEDABAD!F9+MEHSANA!F9 -> 1091 | G9: =AHMEDABAD!G9+MEHSANA!G9 -> 0 | H9: =AHMEDABAD!H9+MEHSANA!H9 -> 0 | I9: =AHMEDABAD!I9+MEHSANA!I9 -> 1014 | J9: =AHMEDABAD!J9+MEHSANA!J9 -> 1393 | K9: =AHMEDABAD!K9+MEHSANA!K9 -> 146 | L9: =AHMEDABAD!L9+MEHSANA!L9 -> 280 | ... AB9: =AHMEDABAD!AB9+MEHSANA!AB9 -> 0
B10: 8 | C10: SIMYL-LBW 400 GM | D10: 402.71 | E10: =AHMEDABAD!E10+MEHSANA!E10 -> 62 | F10: =AHMEDABAD!F10+MEHSANA!F10 -> 160 | G10: =AHMEDABAD!G10+MEHSANA!G10 -> 0 | H10: =AHMEDABAD!H10+MEHSANA!H10 -> 0 | I10: =AHMEDABAD!I10+MEHSANA!I10 -> 48 | J10: =AHMEDABAD!J10+MEHSANA!J10 -> 129 | K10: =AHMEDABAD!K10+MEHSANA!K10 -> 0 | L10: =AHMEDABAD!L10+MEHSANA!L10 -> 0 | ... AB10: =AHMEDABAD!AB10+MEHSANA!AB10 -> 0
B11: 9 | C11: ZEFRICH CHOCOLATE 200 GM | D11: 250.17 | E11: =AHMEDABAD!E11+MEHSANA!E11 -> 150 | F11: =AHMEDABAD!F11+MEHSANA!F11 -> 337 | G11: =AHMEDABAD!G11+MEHSANA!G11 -> 0 | H11: =AHMEDABAD!H11+MEHSANA!H11 -> 0 | I11: =AHMEDABAD!I11+MEHSANA!I11 -> 117 | J11: =AHMEDABAD!J11+MEHSANA!J11 -> 393 | K11: =AHMEDABAD!K11+MEHSANA!K11 -> 0 | L11: =AHMEDABAD!L11+MEHSANA!L11 -> 66 | ... AB11: =AHMEDABAD!AB11+MEHSANA!AB11 -> 0
B12: 10 | C12: ZEFRICH MILK MASALA 200 GM | D12: 250.17 | E12: =AHMEDABAD!E12+MEHSANA!E12 -> 76 | F12: =AHMEDABAD!F12+MEHSANA!F12 -> 258 | G12: =AHMEDABAD!G12+MEHSANA!G12 -> 0 | H12: =AHMEDABAD!H12+MEHSANA!H12 -> 0 | I12: =AHMEDABAD!I12+MEHSANA!I12 -> 96 | J12: =AHMEDABAD!J12+MEHSANA!J12 -> 296 | K12: =AHMEDABAD!K12+MEHSANA!K12 -> 0 | L12: =AHMEDABAD!L12+MEHSANA!L12 -> 0 | ... AB12: =AHMEDABAD!AB12+MEHSANA!AB12 -> 0
B13: 11 | C13: ZEFRICH HP M M 200 GM | D13: 228.82 | E13: =AHMEDABAD!E13+MEHSANA!E13 -> 13 | F13: =AHMEDABAD!F13+MEHSANA!F13 -> 77 | G13: =AHMEDABAD!G13+MEHSANA!G13 -> 0 | H13: =AHMEDABAD!H13+MEHSANA!H13 -> 0 | I13: =AHMEDABAD!I13+MEHSANA!I13 -> 26 | J13: =AHMEDABAD!J13+MEHSANA!J13 -> 136 | K13: =AHMEDABAD!K13+MEHSANA!K13 -> 1 | L13: =AHMEDABAD!L13+MEHSANA!L13 -> 26 | ... AB13: =AHMEDABAD!AB13+MEHSANA!AB13 -> 0
B14: 12 | C14: ZIORAL DROPS 15 ML | D14: 56.38 | E14: =AHMEDABAD!E14+MEHSANA!E14 -> 586 | F14: =AHMEDABAD!F14+MEHSANA!F14 -> 764 | G14: =AHMEDABAD!G14+MEHSANA!G14 -> 0 | H14: =AHMEDABAD!H14+MEHSANA!H14 -> 0 | I14: =AHMEDABAD!I14+MEHSANA!I14 -> 722 | J14: =AHMEDABAD!J14+MEHSANA!J14 -> 970 | K14: =AHMEDABAD!K14+MEHSANA!K14 -> 73 | L14: =AHMEDABAD!L14+MEHSANA!L14 -> 164 | ... AB14: =AHMEDABAD!AB14+MEHSANA!AB14 -> 0
B15: 13 | C15: ZIORAL ORAL SYP 100 ML | D15: 70.14 | E15: =AHMEDABAD!E15+MEHSANA!E15 -> 722 | F15: =AHMEDABAD!F15+MEHSANA!F15 -> 805 | G15: =AHMEDABAD!G15+MEHSANA!G15 -> 0 | H15: =AHMEDABAD!H15+MEHSANA!H15 -> 0 | I15: =AHMEDABAD!I15+MEHSANA!I15 -> 568 | J15: =AHMEDABAD!J15+MEHSANA!J15 -> 1072 | K15: =AHMEDABAD!K15+MEHSANA!K15 -> 154 | L15: =AHMEDABAD!L15+MEHSANA!L15 -> 149 | ... AB15: =AHMEDABAD!AB15+MEHSANA!AB15 -> 0
B16: 14 | E16: =AHMEDABAD!E16+MEHSANA!E16 -> 0 | F16: =AHMEDABAD!F16+MEHSANA!F16 -> 0 | G16: =AHMEDABAD!G16+MEHSANA!G16 -> 0 | H16: =AHMEDABAD!H16+MEHSANA!H16 -> 0 | I16: =AHMEDABAD!I16+MEHSANA!I16 -> 0 | J16: =AHMEDABAD!J16+MEHSANA!J16 -> 0 | K16: =AHMEDABAD!K16+MEHSANA!K16 -> 0 | L16: =AHMEDABAD!L16+MEHSANA!L16 -> 0 | ... AB16: =AHMEDABAD!AB16+MEHSANA!AB16 -> 0
C17: Total | E17: =SUMPRODUCT($D3:$D16,E3:E16)/100000 -> 8.2608552 | F17: =SUMPRODUCT($D3:$D16,F3:F16)/100000 -> 11.201961 | G17: =SUMPRODUCT($D3:$D16,G3:G16)/100000 -> 0 | H17: =SUMPRODUCT($D3:$D16,H3:H16)/100000 -> 0 | I17: =SUMPRODUCT($D3:$D16,I3:I16)/100000 -> 6.9846222 | J17: =SUMPRODUCT($D3:$D16,J3:J16)/100000 -> 12.662306 | K17: =SUMPRODUCT($D3:$D16,K3:K16)/100000 -> 0.6481008 | L17: =SUMPRODUCT($D3:$D16,L3:L16)/100000 -> 1.7580471 | ... AB17: =SUMPRODUCT($D3:$D16,AB3:AB16)/100000 -> 0
B19: CODE | C19: PRODUCT | E19: S.S. | F19: C.S. | G19: S.S. | H19: C.S. | I19: S.S. | J19: C.S. | K19: S.S. | L19: C.S. | M19: S.S. | N19: C.S. | O19: S.S. | P19: C.S. | Q19: S.S. | R19: C.S. | S19: S.S. | T19: C.S. | U19: S.S. | V19: C.S. | W19: S.S. | X19: C.S. | Y19: S.S. | Z19: C.S. | AA19: S.S. | AB19: C.S.
C20: MUMMUM GROUP | E20: =SUMPRODUCT($D$4:$D$5:$D$6,E4:E5:E6)/100000 -> 0.7715491 | F20: =SUMPRODUCT($D$4:$D$5:$D$6,F4:F5:F6)/100000 -> 2.0168409 | G20: =SUMPRODUCT($D$2:$D$3:$D$4,G2:G3:G4)/100000 -> 0 | H20: =SUMPRODUCT($D$2:$D$3:$D$4,H2:H3:H4)/100000 -> 0 | I20: =SUMPRODUCT($D$2:$D$3:$D$4,I2:I3:I4)/100000 -> 0.0760148 | J20: =SUMPRODUCT($D$2:$D$3:$D$4,J2:J3:J4)/100000 -> 0.3828338 | K20: =SUMPRODUCT($D$2:$D$3:$D$4,K2:K3:K4)/100000 -> 0.001858 | L20: =SUMPRODUCT($D$2:$D$3:$D$4,L2:L3:L4)/100000 -> 0.006503 | M20: =SUMPRODUCT($D$2:$D$3:$D$4,M2:M3:M4)/100000 -> 0 | N20: =SUMPRODUCT($D$2:$D$3:$D$4,N2:N3:N4)/100000 -> 0 | ... AB20: =SUMPRODUCT($D$2:$D$3:$D$4,AB2:AB3:AB4)/100000 -> 0
C21: SIMYL GROUP | E21: =SUMPRODUCT($D$7:$D$8:$D$9:$D$10,E7:E8:E9:E10)/100000 -> 6.0490167 | F21: =SUMPRODUCT($D$7:$D$8:$D$9:$D$10,F7:F8:F9:F10)/100000 -> 6.4275019 | G21: =SUMPRODUCT($D$5:$D$6:$D$7:$D$8,G5:G6:G7:G8)/100000 -> 0 | H21: =SUMPRODUCT($D$5:$D$6:$D$7:$D$8,H5:H6:H7:H8)/100000 -> 0 | I21: =SUMPRODUCT($D$5:$D$6:$D$7:$D$8,I5:I6:I7:I8)/100000 -> 2.9972577 | J21: =SUMPRODUCT($D$5:$D$6:$D$7:$D$8,J5:J6:J7:J8)/100000 -> 5.2388604 | K21: =SUMPRODUCT($D$5:$D$6:$D$7:$D$8,K5:K6:K7:K8)/100000 -> 0.1607044 | L21: =SUMPRODUCT($D$5:$D$6:$D$7:$D$8,L5:L6:L7:L8)/100000 -> 0.6892709 | M21: =SUMPRODUCT($D$5:$D$6:$D$7:$D$8,M5:M6:M7:M8)/100000 -> 0 | N21: =SUMPRODUCT($D$5:$D$6:$D$7:$D$8,N5:N6:N7:N8)/100000 -> 0 | ... AB21: =SUMPRODUCT($D$5:$D$6:$D$7:$D$8,AB5:AB6:AB7:AB8)/100000 -> 0
C22: ZEFRICH GROUP | E22: =SUMPRODUCT($D$11:$D$12:$D$13,E11:E12:E13)/100000 -> 0.5951308 | F22: =SUMPRODUCT($D$11:$D$12:$D$13,F11:F12:F13)/100000 -> 1.6647029 | G22: =SUMPRODUCT($D$9:$D$10:$D$11,G9:G10:G11)/100000 -> 0 | H22: =SUMPRODUCT($D$9:$D$10:$D$11,H9:H10:H11)/100000 -> 0 | I22: =SUMPRODUCT($D$9:$D$10:$D$11,I9:I10:I11)/100000 -> 2.8062345 | J22: =SUMPRODUCT($D$9:$D$10:$D$11,J9:J10:J11)/100000 -> 4.6901266 | K22: =SUMPRODUCT($D$9:$D$10:$D$11,K9:K10:K11)/100000 -> 0.3340772 | L22: =SUMPRODUCT($D$9:$D$10:$D$11,L9:L10:L11)/100000 -> 0.8058082 | M22: =SUMPRODUCT($D$9:$D$10:$D$11,M9:M10:M11)/100000 -> 0 | N22: =SUMPRODUCT($D$9:$D$10:$D$11,N9:N10:N11)/100000 -> 0 | ... AB22: =SUMPRODUCT($D$9:$D$10:$D$11,AB9:AB10:AB11)/100000 -> 0
C23: ZIORAL GROUP | E23: =SUMPRODUCT($D$14:$D$15,E14:E15)/100000 -> 0.8367976 | F23: =SUMPRODUCT($D$14:$D$15,F14:F15)/100000 -> 0.9953702 | G23: =SUMPRODUCT($D$12:$D$13,G12:G13)/100000 -> 0 | H23: =SUMPRODUCT($D$12:$D$13,H12:H13)/100000 -> 0 | I23: =SUMPRODUCT($D$12:$D$13,I12:I13)/100000 -> 0.2996564 | J23: =SUMPRODUCT($D$12:$D$13,J12:J13)/100000 -> 1.0516984 | K23: =SUMPRODUCT($D$12:$D$13,K12:K13)/100000 -> 0.0022882 | L23: =SUMPRODUCT($D$12:$D$13,L12:L13)/100000 -> 0.0594932 | M23: =SUMPRODUCT($D$12:$D$13,M12:M13)/100000 -> 0 | N23: =SUMPRODUCT($D$12:$D$13,N12:N13)/100000 -> 0 | ... AB23: =SUMPRODUCT($D$12:$D$13,AB12:AB13)/100000 -> 0
C24: Total | E24: =SUM(E20:E23) -> 8.2524942 | F24: =SUM(F20:F23) -> 11.104416 | G24: =SUM(G20:G23) -> 0 | H24: =SUM(H20:H23) -> 0 | I24: =SUM(I20:I23) -> 6.1791634 | J24: =SUM(J20:J23) -> 11.363519 | K24: =SUM(K20:K23) -> 0.4989278 | L24: =SUM(L20:L23) -> 1.5610753 | ... AB24: =SUM(AB20:AB23) -> 0

Sheet DM RAJKOT
A1: 2026_27 | C1: VACANT - DM RAJKOT | E1: APR'26 | G1: MAY'26 | I1: JUN'26 | K1: JUL'26 | M1: AUG'26 | O1: SEP'26 | Q1: OCT'26 | S1: NOV'26 | U1: DEC'26 | W1: JAN'26 | Y1: FEB'26 | AA1: MAR'26
B2: S.No | C2: PRODUCT | D2: PTS | E2: S.S. | F2: C.S. | G2: S.S. | H2: C.S. | I2: S.S. | J2: C.S. | K2: S.S. | L2: C.S. | M2: S.S. | N2: C.S. | O2: S.S. | P2: C.S. | Q2: S.S. | R2: C.S. | S2: S.S. | T2: C.S. | U2: S.S. | V2: C.S. | W2: S.S. | X2: C.S. | Y2: S.S. | Z2: C.S. | AA2: S.S. | AB2: C.S.
A3: Total Sales | B3: 1 | C3: CALYUMM P SUP 200 ML | D3: 92.9 | E3: =RAJKOT!E3+BHAVNAGAR!E3+JUNAGADH!E3+BHUJ!E3 -> 34 | F3: =RAJKOT!F3+BHAVNAGAR!F3+JUNAGADH!F3+BHUJ!F3 -> 124 | G3: =RAJKOT!G3+BHAVNAGAR!G3+JUNAGADH!G3+BHUJ!G3 -> 0 | H3: =RAJKOT!H3+BHAVNAGAR!H3+JUNAGADH!H3+BHUJ!H3 -> 0 | I3: =RAJKOT!I3+BHAVNAGAR!I3+JUNAGADH!I3+BHUJ!I3 -> 0 | J3: =RAJKOT!J3+BHAVNAGAR!J3+JUNAGADH!J3+BHUJ!J3 -> 0 | K3: =RAJKOT!K3+BHAVNAGAR!K3+JUNAGADH!K3+BHUJ!K3 -> 0 | L3: =RAJKOT!L3+BHAVNAGAR!L3+JUNAGADH!L3+BHUJ!L3 -> 0 | ... AB3: =RAJKOT!AB3+BHAVNAGAR!AB3+JUNAGADH!AB3+BHUJ!AB3 -> 0
B4: 2 | C4: MUMMUM-1 200 GM | D4: 154.38 | E4: =RAJKOT!E4+BHAVNAGAR!E4+JUNAGADH!E4+BHUJ!E4 -> 309 | F4: =RAJKOT!F4+BHAVNAGAR!F4+JUNAGADH!F4+BHUJ!F4 -> 401 | G4: =RAJKOT!G4+BHAVNAGAR!G4+JUNAGADH!G4+BHUJ!G4 -> 0 | H4: =RAJKOT!H4+BHAVNAGAR!H4+JUNAGADH!H4+BHUJ!H4 -> 0 | I4: =RAJKOT!I4+BHAVNAGAR!I4+JUNAGADH!I4+BHUJ!I4 -> 0 | J4: =RAJKOT!J4+BHAVNAGAR!J4+JUNAGADH!J4+BHUJ!J4 -> 0 | K4: =RAJKOT!K4+BHAVNAGAR!K4+JUNAGADH!K4+BHUJ!K4 -> 0 | L4: =RAJKOT!L4+BHAVNAGAR!L4+JUNAGADH!L4+BHUJ!L4 -> 0 | ... AB4: =RAJKOT!AB4+BHAVNAGAR!AB4+JUNAGADH!AB4+BHUJ!AB4 -> 0
B5: 3 | C5: MUMMUM-1 400 GM | D5: 283.73 | E5: =RAJKOT!E5+BHAVNAGAR!E5+JUNAGADH!E5+BHUJ!E5 -> 440 | F5: =RAJKOT!F5+BHAVNAGAR!F5+JUNAGADH!F5+BHUJ!F5 -> 372 | G5: =RAJKOT!G5+BHAVNAGAR!G5+JUNAGADH!G5+BHUJ!G5 -> 0 | H5: =RAJKOT!H5+BHAVNAGAR!H5+JUNAGADH!H5+BHUJ!H5 -> 0 | I5: =RAJKOT!I5+BHAVNAGAR!I5+JUNAGADH!I5+BHUJ!I5 -> 0 | J5: =RAJKOT!J5+BHAVNAGAR!J5+JUNAGADH!J5+BHUJ!J5 -> 0 | K5: =RAJKOT!K5+BHAVNAGAR!K5+JUNAGADH!K5+BHUJ!K5 -> 0 | L5: =RAJKOT!L5+BHAVNAGAR!L5+JUNAGADH!L5+BHUJ!L5 -> 0 | ... AB5: =RAJKOT!AB5+BHAVNAGAR!AB5+JUNAGADH!AB5+BHUJ!AB5 -> 0
B6: 4 | C6: MUMMUM-2 400 GM | D6: 344.75 | E6: =RAJKOT!E6+BHAVNAGAR!E6+JUNAGADH!E6+BHUJ!E6 -> 299 | F6: =RAJKOT!F6+BHAVNAGAR!F6+JUNAGADH!F6+BHUJ!F6 -> 320 | G6: =RAJKOT!G6+BHAVNAGAR!G6+JUNAGADH!G6+BHUJ!G6 -> 0 | H6: =RAJKOT!H6+BHAVNAGAR!H6+JUNAGADH!H6+BHUJ!H6 -> 0 | I6: =RAJKOT!I6+BHAVNAGAR!I6+JUNAGADH!I6+BHUJ!I6 -> 0 | J6: =RAJKOT!J6+BHAVNAGAR!J6+JUNAGADH!J6+BHUJ!J6 -> 0 | K6: =RAJKOT!K6+BHAVNAGAR!K6+JUNAGADH!K6+BHUJ!K6 -> 0 | L6: =RAJKOT!L6+BHAVNAGAR!L6+JUNAGADH!L6+BHUJ!L6 -> 0 | ... AB6: =RAJKOT!AB6+BHAVNAGAR!AB6+JUNAGADH!AB6+BHUJ!AB6 -> 0
B7: 5 | C7: SIMYL MCT 200 GM | D7: 208.06 | E7: =RAJKOT!E7+BHAVNAGAR!E7+JUNAGADH!E7+BHUJ!E7 -> 84 | F7: =RAJKOT!F7+BHAVNAGAR!F7+JUNAGADH!F7+BHUJ!F7 -> 211 | G7: =RAJKOT!G7+BHAVNAGAR!G7+JUNAGADH!G7+BHUJ!G7 -> 0 | H7: =RAJKOT!H7+BHAVNAGAR!H7+JUNAGADH!H7+BHUJ!H7 -> 0 | I7: =RAJKOT!I7+BHAVNAGAR!I7+JUNAGADH!I7+BHUJ!I7 -> 0 | J7: =RAJKOT!J7+BHAVNAGAR!J7+JUNAGADH!J7+BHUJ!J7 -> 0 | K7: =RAJKOT!K7+BHAVNAGAR!K7+JUNAGADH!K7+BHUJ!K7 -> 0 | L7: =RAJKOT!L7+BHAVNAGAR!L7+JUNAGADH!L7+BHUJ!L7 -> 0 | ... AB7: =RAJKOT!AB7+BHAVNAGAR!AB7+JUNAGADH!AB7+BHUJ!AB7 -> 0
B8: 6 | C8: SIMYL MCT 400 GM | D8: 399.65 | E8: =RAJKOT!E8+BHAVNAGAR!E8+JUNAGADH!E8+BHUJ!E8 -> 54 | F8: =RAJKOT!F8+BHAVNAGAR!F8+JUNAGADH!F8+BHUJ!F8 -> 143 | G8: =RAJKOT!G8+BHAVNAGAR!G8+JUNAGADH!G8+BHUJ!G8 -> 0 | H8: =RAJKOT!H8+BHAVNAGAR!H8+JUNAGADH!H8+BHUJ!H8 -> 0 | I8: =RAJKOT!I8+BHAVNAGAR!I8+JUNAGADH!I8+BHUJ!I8 -> 0 | J8: =RAJKOT!J8+BHAVNAGAR!J8+JUNAGADH!J8+BHUJ!J8 -> 0 | K8: =RAJKOT!K8+BHAVNAGAR!K8+JUNAGADH!K8+BHUJ!K8 -> 0 | L8: =RAJKOT!L8+BHAVNAGAR!L8+JUNAGADH!L8+BHUJ!L8 -> 0 | ... AB8: =RAJKOT!AB8+BHAVNAGAR!AB8+JUNAGADH!AB8+BHUJ!AB8 -> 0
B9: 7 | C9: SIMYL MCT OIL (HDPE) 100 ML | D9: 228.82 | E9: =RAJKOT!E9+BHAVNAGAR!E9+JUNAGADH!E9+BHUJ!E9 -> 1271 | F9: =RAJKOT!F9+BHAVNAGAR!F9+JUNAGADH!F9+BHUJ!F9 -> 978 | G9: =RAJKOT!G9+BHAVNAGAR!G9+JUNAGADH!G9+BHUJ!G9 -> 0 | H9: =RAJKOT!H9+BHAVNAGAR!H9+JUNAGADH!H9+BHUJ!H9 -> 0 | I9: =RAJKOT!I9+BHAVNAGAR!I9+JUNAGADH!I9+BHUJ!I9 -> 0 | J9: =RAJKOT!J9+BHAVNAGAR!J9+JUNAGADH!J9+BHUJ!J9 -> 0 | K9: =RAJKOT!K9+BHAVNAGAR!K9+JUNAGADH!K9+BHUJ!K9 -> 0 | L9: =RAJKOT!L9+BHAVNAGAR!L9+JUNAGADH!L9+BHUJ!L9 -> 0 | ... AB9: =RAJKOT!AB9+BHAVNAGAR!AB9+JUNAGADH!AB9+BHUJ!AB9 -> 0
B10: 8 | C10: SIMYL-LBW 400 GM | D10: 402.71 | E10: =RAJKOT!E10+BHAVNAGAR!E10+JUNAGADH!E10+BHUJ!E10 -> 69 | F10: =RAJKOT!F10+BHAVNAGAR!F10+JUNAGADH!F10+BHUJ!F10 -> 142 | G10: =RAJKOT!G10+BHAVNAGAR!G10+JUNAGADH!G10+BHUJ!G10 -> 0 | H10: =RAJKOT!H10+BHAVNAGAR!H10+JUNAGADH!H10+BHUJ!H10 -> 0 | I10: =RAJKOT!I10+BHAVNAGAR!I10+JUNAGADH!I10+BHUJ!I10 -> 0 | J10: =RAJKOT!J10+BHAVNAGAR!J10+JUNAGADH!J10+BHUJ!J10 -> 0 | K10: =RAJKOT!K10+BHAVNAGAR!K10+JUNAGADH!K10+BHUJ!K10 -> 0 | L10: =RAJKOT!L10+BHAVNAGAR!L10+JUNAGADH!L10+BHUJ!L10 -> 0 | ... AB10: =RAJKOT!AB10+BHAVNAGAR!AB10+JUNAGADH!AB10+BHUJ!AB10 -> 0
B11: 9 | C11: ZEFRICH CHOCOLATE 200 GM | D11: 250.17 | E11: =RAJKOT!E11+BHAVNAGAR!E11+JUNAGADH!E11+BHUJ!E11 -> 52 | F11: =RAJKOT!F11+BHAVNAGAR!F11+JUNAGADH!F11+BHUJ!F11 -> 203 | G11: =RAJKOT!G11+BHAVNAGAR!G11+JUNAGADH!G11+BHUJ!G11 -> 0 | H11: =RAJKOT!H11+BHAVNAGAR!H11+JUNAGADH!H11+BHUJ!H11 -> 0 | I11: =RAJKOT!I11+BHAVNAGAR!I11+JUNAGADH!I11+BHUJ!I11 -> 0 | J11: =RAJKOT!J11+BHAVNAGAR!J11+JUNAGADH!J11+BHUJ!J11 -> 0 | K11: =RAJKOT!K11+BHAVNAGAR!K11+JUNAGADH!K11+BHUJ!K11 -> 0 | L11: =RAJKOT!L11+BHAVNAGAR!L11+JUNAGADH!L11+BHUJ!L11 -> 0 | ... AB11: =RAJKOT!AB11+BHAVNAGAR!AB11+JUNAGADH!AB11+BHUJ!AB11 -> 0
B12: 10 | C12: ZEFRICH MILK MASALA 200 GM | D12: 250.17 | E12: =RAJKOT!E12+BHAVNAGAR!E12+JUNAGADH!E12+BHUJ!E12 -> 73 | F12: =RAJKOT!F12+BHAVNAGAR!F12+JUNAGADH!F12+BHUJ!F12 -> 233 | G12: =RAJKOT!G12+BHAVNAGAR!G12+JUNAGADH!G12+BHUJ!G12 -> 0 | H12: =RAJKOT!H12+BHAVNAGAR!H12+JUNAGADH!H12+BHUJ!H12 -> 0 | I12: =RAJKOT!I12+BHAVNAGAR!I12+JUNAGADH!I12+BHUJ!I12 -> 0 | J12: =RAJKOT!J12+BHAVNAGAR!J12+JUNAGADH!J12+BHUJ!J12 -> 0 | K12: =RAJKOT!K12+BHAVNAGAR!K12+JUNAGADH!K12+BHUJ!K12 -> 0 | L12: =RAJKOT!L12+BHAVNAGAR!L12+JUNAGADH!L12+BHUJ!L12 -> 0 | ... AB12: =RAJKOT!AB12+BHAVNAGAR!AB12+JUNAGADH!AB12+BHUJ!AB12 -> 0
B13: 11 | C13: ZEFRICH HP M M 200 GM | D13: 228.82 | E13: =RAJKOT!E13+BHAVNAGAR!E13+JUNAGADH!E13+BHUJ!E13 -> 33 | F13: =RAJKOT!F13+BHAVNAGAR!F13+JUNAGADH!F13+BHUJ!F13 -> 94 | G13: =RAJKOT!G13+BHAVNAGAR!G13+JUNAGADH!G13+BHUJ!G13 -> 0 | H13: =RAJKOT!H13+BHAVNAGAR!H13+JUNAGADH!H13+BHUJ!H13 -> 0 | I13: =RAJKOT!I13+BHAVNAGAR!I13+JUNAGADH!I13+BHUJ!I13 -> 0 | J13: =RAJKOT!J13+BHAVNAGAR!J13+JUNAGADH!J13+BHUJ!J13 -> 0 | K13: =RAJKOT!K13+BHAVNAGAR!K13+JUNAGADH!K13+BHUJ!K13 -> 0 | L13: =RAJKOT!L13+BHAVNAGAR!L13+JUNAGADH!L13+BHUJ!L13 -> 0 | ... AB13: =RAJKOT!AB13+BHAVNAGAR!AB13+JUNAGADH!AB13+BHUJ!AB13 -> 0
B14: 12 | C14: ZIORAL DROPS 15 ML | D14: 56.38 | E14: =RAJKOT!E14+BHAVNAGAR!E14+JUNAGADH!E14+BHUJ!E14 -> 317 | F14: =RAJKOT!F14+BHAVNAGAR!F14+JUNAGADH!F14+BHUJ!F14 -> 556 | G14: =RAJKOT!G14+BHAVNAGAR!G14+JUNAGADH!G14+BHUJ!G14 -> 0 | H14: =RAJKOT!H14+BHAVNAGAR!H14+JUNAGADH!H14+BHUJ!H14 -> 0 | I14: =RAJKOT!I14+BHAVNAGAR!I14+JUNAGADH!I14+BHUJ!I14 -> 0 | J14: =RAJKOT!J14+BHAVNAGAR!J14+JUNAGADH!J14+BHUJ!J14 -> 0 | K14: =RAJKOT!K14+BHAVNAGAR!K14+JUNAGADH!K14+BHUJ!K14 -> 0 | L14: =RAJKOT!L14+BHAVNAGAR!L14+JUNAGADH!L14+BHUJ!L14 -> 0 | ... AB14: =RAJKOT!AB14+BHAVNAGAR!AB14+JUNAGADH!AB14+BHUJ!AB14 -> 0
B15: 13 | C15: ZIORAL ORAL SYP 100 ML | D15: 70.14 | E15: =RAJKOT!E15+BHAVNAGAR!E15+JUNAGADH!E15+BHUJ!E15 -> 145 | F15: =RAJKOT!F15+BHAVNAGAR!F15+JUNAGADH!F15+BHUJ!F15 -> 490 | G15: =RAJKOT!G15+BHAVNAGAR!G15+JUNAGADH!G15+BHUJ!G15 -> 0 | H15: =RAJKOT!H15+BHAVNAGAR!H15+JUNAGADH!H15+BHUJ!H15 -> 0 | I15: =RAJKOT!I15+BHAVNAGAR!I15+JUNAGADH!I15+BHUJ!I15 -> 0 | J15: =RAJKOT!J15+BHAVNAGAR!J15+JUNAGADH!J15+BHUJ!J15 -> 0 | K15: =RAJKOT!K15+BHAVNAGAR!K15+JUNAGADH!K15+BHUJ!K15 -> 0 | L15: =RAJKOT!L15+BHAVNAGAR!L15+JUNAGADH!L15+BHUJ!L15 -> 0 | ... AB15: =RAJKOT!AB15+BHAVNAGAR!AB15+JUNAGADH!AB15+BHUJ!AB15 -> 0
B16: 14 | E16: =RAJKOT!E16+BHAVNAGAR!E16+JUNAGADH!E16+BHUJ!E16 -> 0 | F16: =RAJKOT!F16+BHAVNAGAR!F16+JUNAGADH!F16+BHUJ!F16 -> 0 | G16: =RAJKOT!G16+BHAVNAGAR!G16+JUNAGADH!G16+BHUJ!G16 -> 0 | H16: =RAJKOT!H16+BHAVNAGAR!H16+JUNAGADH!H16+BHUJ!H16 -> 0 | I16: =RAJKOT!I16+BHAVNAGAR!I16+JUNAGADH!I16+BHUJ!I16 -> 0 | J16: =RAJKOT!J16+BHAVNAGAR!J16+JUNAGADH!J16+BHUJ!J16 -> 0 | K16: =RAJKOT!K16+BHAVNAGAR!K16+JUNAGADH!K16+BHUJ!K16 -> 0 | L16: =RAJKOT!L16+BHAVNAGAR!L16+JUNAGADH!L16+BHUJ!L16 -> 0 | ... AB16: =RAJKOT!AB16+BHAVNAGAR!AB16+JUNAGADH!AB16+BHUJ!AB16 -> 0
C17: Total | E17: =SUMPRODUCT($D3:$D16,E3:E16)/100000 -> 7.0332389 | F17: =SUMPRODUCT($D3:$D16,F3:F16)/100000 -> 8.6761401 | G17: =SUMPRODUCT($D3:$D16,G3:G16)/100000 -> 0 | H17: =SUMPRODUCT($D3:$D16,H3:H16)/100000 -> 0 | I17: =SUMPRODUCT($D3:$D16,I3:I16)/100000 -> 0 | J17: =SUMPRODUCT($D3:$D16,J3:J16)/100000 -> 0 | K17: =SUMPRODUCT($D3:$D16,K3:K16)/100000 -> 0 | L17: =SUMPRODUCT($D3:$D16,L3:L16)/100000 -> 0 | ... AB17: =SUMPRODUCT($D3:$D16,AB3:AB16)/100000 -> 0
B19: CODE | C19: PRODUCT | E19: S.S. | F19: C.S. | G19: S.S. | H19: C.S. | I19: S.S. | J19: C.S. | K19: S.S. | L19: C.S. | M19: S.S. | N19: C.S. | O19: S.S. | P19: C.S. | Q19: S.S. | R19: C.S. | S19: S.S. | T19: C.S. | U19: S.S. | V19: C.S. | W19: S.S. | X19: C.S. | Y19: S.S. | Z19: C.S. | AA19: S.S. | AB19: C.S.
